Workbook

Sheet Matches
A1: Match ID | B1: Date | C1: Team | D1: Score | E1: Goals Team A | F1: Goals Team B | G1: MVP
A2: 1 | B2: 45974 | C2: Team A vs Team B | D2: 7-7 | E2: =VALUE(LEFT(D2, FIND("-", D2)-1)) -> 7 | F2: =VALUE(MID(D2, FIND("-", D2)+1, 10)) -> 7 | G2: Pranav
A3: 2 | B3: 45981 | C3: Team A vs Team B | D3: 5-7 | E3: =VALUE(LEFT(D3, FIND("-", D3)-1)) -> 5 | F3: =VALUE(MID(D3, FIND("-", D3)+1, 10)) -> 7 | G3: Pranav
A4: 3 | B4: 45988 | C4: Team A vs Team B | D4: 7-9 | E4: =VALUE(LEFT(D4, FIND("-", D4)-1)) -> 7 | F4: =VALUE(MID(D4, FIND("-", D4)+1, 10)) -> 9 | G4: Musta
A5: 4 | B5: 45995 | C5: Team A vs Team B | D5: 13-8 | E5: =VALUE(LEFT(D5, FIND("-", D5)-1)) -> 13 | F5: =VALUE(MID(D5, FIND("-", D5)+1, 10)) -> 8 | G5: Musta
A6: 5 | B6: 46002 | C6: Team A vs Team B | D6: 10-8 | E6: =VALUE(LEFT(D6, FIND("-", D6)-1)) -> 10 | F6: =VALUE(MID(D6, FIND("-", D6)+1, 10)) -> 8 | G6: Diego
A7: 6 | B7: 46009 | C7: Team A vs Team B | D7: 16-17 | E7: =VALUE(LEFT(D7, FIND("-", D7)-1)) -> 16 | F7: =VALUE(MID(D7, FIND("-", D7)+1, 10)) -> 17 | G7: Jose
A8: 7 | B8: 46030 | C8: Team A vs Team B | D8: 6-11 | E8: =VALUE(LEFT(D8, FIND("-", D8)-1)) -> 6 | F8: =VALUE(MID(D8, FIND("-", D8)+1, 10)) -> 11 | G8: Stefano
A9: 8 | B9: 46037 | C9: Team A vs Team B | D9: 5-5 | E9: =VALUE(LEFT(D9, FIND("-", D9)-1)) -> 5 | F9: =VALUE(MID(D9, FIND("-", D9)+1, 10)) -> 5 | G9: Jose
A10: 9 | B10: 46044 | C10: Team A vs Team B | D10: 3-6 | E10: =VALUE(LEFT(D10, FIND("-", D10)-1)) -> 3 | F10: =VALUE(MID(D10, FIND("-", D10)+1, 10)) -> 6 | G10: Andreadb
A11: 10 | B11: 46051 | C11: Team A vs Team B | D11: 6-5 | E11: =VALUE(LEFT(D11, FIND("-", D11)-1)) -> 6 | F11: =VALUE(MID(D11, FIND("-", D11)+1, 10)) -> 5 | G11: Enrico
A12: 11 | B12: 46058 | C12: Team A vs Team B | D12: 2-3 | E12: =VALUE(LEFT(D12, FIND("-", D12)-1)) -> 2 | F12: =VALUE(MID(D12, FIND("-", D12)+1, 10)) -> 3 | G12: Tano
A13: 12 | B13: 46065 | C13: Team A vs Team B | D13: 5-4 | E13: =VALUE(LEFT(D13, FIND("-", D13)-1)) -> 5 | F13: =VALUE(MID(D13, FIND("-", D13)+1, 10)) -> 4 | G13: Dario
... A15: 14 | B15: 46072 | C15: Team A vs Team B | D15: 6-6 | E15: =VALUE(LEFT(D15, FIND("-", D15)-1)) -> 6 | F15: =VALUE(MID(D15, FIND("-", D15)+1, 10)) -> 6 | G15: Andrea M

Sheet Team Lineups
A1: Match ID | B1: Date | C1: Player Name | D1: Team (A/B) | E1: Team Score | F1: Team Conceded | G1: Result | H1: Goals Scored | I1: Assists | J1: Own Goals | K1: Unique Team ID
A2: 1 | B2: =VLOOKUP(A2,Matches!A:B,2,FALSE) -> 45974 | C2: Gioele | D2: A | E2: =IF(D2="A", INDEX(Matches!$E:$E, MATCH(A2, Matches!$A:$A, 0)), INDEX(Matches!$F:$F, MATCH(A2, Matches!$A:$A, 0))) -> 7 | F2: =IF(D2="A", INDEX(Matches!$F:$F, MATCH(A2, Matches!$A:$A, 0)), INDEX(Matches!$E:$E, MATCH(A2, Matches!$A:$A, 0))) -> 7 | G2: =IF(E2>F2,"Win",IF(E2<F2,"Loss","Draw")) -> Draw | H2: 2 | I2: 2 | K2: =A2&"_"&D2 -> 1_A
A3: 1 | B3: =VLOOKUP(A3,Matches!A:B,2,FALSE) -> 45974 | C3: Gianmarco | D3: A | E3: =IF(D3="A", INDEX(Matches!$E:$E, MATCH(A3, Matches!$A:$A, 0)), INDEX(Matches!$F:$F, MATCH(A3, Matches!$A:$A, 0))) -> 7 | F3: =IF(D3="A", INDEX(Matches!$F:$F, MATCH(A3, Matches!$A:$A, 0)), INDEX(Matches!$E:$E, MATCH(A3, Matches!$A:$A, 0))) -> 7 | G3: =IF(E3>F3,"Win",IF(E3<F3,"Loss","Draw")) -> Draw | H3: 2 | I3: 0 | K3: =A3&"_"&D3 -> 1_A
A4: 1 | B4: =VLOOKUP(A4,Matches!A:B,2,FALSE) -> 45974 | C4: Musta | D4: A | E4: =IF(D4="A", INDEX(Matches!$E:$E, MATCH(A4, Matches!$A:$A, 0)), INDEX(Matches!$F:$F, MATCH(A4, Matches!$A:$A, 0))) -> 7 | F4: =IF(D4="A", INDEX(Matches!$F:$F, MATCH(A4, Matches!$A:$A, 0)), INDEX(Matches!$E:$E, MATCH(A4, Matches!$A:$A, 0))) -> 7 | G4: =IF(E4>F4,"Win",IF(E4<F4,"Loss","Draw")) -> Draw | H4: 2 | I4: 0 | K4: =A4&"_"&D4 -> 1_A
A5: 1 | B5: =VLOOKUP(A5,Matches!A:B,2,FALSE) -> 45974 | C5: Alessandro D | D5: A | E5: =IF(D5="A", INDEX(Matches!$E:$E, MATCH(A5, Matches!$A:$A, 0)), INDEX(Matches!$F:$F, MATCH(A5, Matches!$A:$A, 0))) -> 7 | F5: =IF(D5="A", INDEX(Matches!$F:$F, MATCH(A5, Matches!$A:$A, 0)), INDEX(Matches!$E:$E, MATCH(A5, Matches!$A:$A, 0))) -> 7 | G5: =IF(E5>F5,"Win",IF(E5<F5,"Loss","Draw")) -> Draw | H5: 0 | I5: 0 | K5: =A5&"_"&D5 -> 1_A
A6: 1 | B6: =VLOOKUP(A6,Matches!A:B,2,FALSE) -> 45974 | C6: Andreadb | D6: A | E6: =IF(D6="A", INDEX(Matches!$E:$E, MATCH(A6, Matches!$A:$A, 0)), INDEX(Matches!$F:$F, MATCH(A6, Matches!$A:$A, 0))) -> 7 | F6: =IF(D6="A", INDEX(Matches!$F:$F, MATCH(A6, Matches!$A:$A, 0)), INDEX(Matches!$E:$E, MATCH(A6, Matches!$A:$A, 0))) -> 7 | G6: =IF(E6>F6,"Win",IF(E6<F6,"Loss","Draw")) -> Draw | H6: 0 | I6: 0 | K6: =A6&"_"&D6 -> 1_A
A7: 1 | B7: =VLOOKUP(A7,Matches!A:B,2,FALSE) -> 45974 | C7: Jose | D7: B | E7: =IF(D7="A", INDEX(Matches!$E:$E, MATCH(A7, Matches!$A:$A, 0)), INDEX(Matches!$F:$F, MATCH(A7, Matches!$A:$A, 0))) -> 7 | F7: =IF(D7="A", INDEX(Matches!$F:$F, MATCH(A7, Matches!$A:$A, 0)), INDEX(Matches!$E:$E, MATCH(A7, Matches!$A:$A, 0))) -> 7 | G7: =IF(E7>F7,"Win",IF(E7<F7,"Loss","Draw")) -> Draw | H7: 0 | I7: 0 | K7: =A7&"_"&D7 -> 1_B
A8: 1 | B8: =VLOOKUP(A8,Matches!A:B,2,FALSE) -> 45974 | C8: Alessandro C | D8: B | E8: =IF(D8="A", INDEX(Matches!$E:$E, MATCH(A8, Matches!$A:$A, 0)), INDEX(Matches!$F:$F, MATCH(A8, Matches!$A:$A, 0))) -> 7 | F8: =IF(D8="A", INDEX(Matches!$F:$F, MATCH(A8, Matches!$A:$A, 0)), INDEX(Matches!$E:$E, MATCH(A8, Matches!$A:$A, 0))) -> 7 | G8: =IF(E8>F8,"Win",IF(E8<F8,"Loss","Draw")) -> Draw | H8: 1 | I8: 0 | K8: =A8&"_"&D8 -> 1_B
A9: 1 | B9: =VLOOKUP(A9,Matches!A:B,2,FALSE) -> 45974 | C9: Lorenzo | D9: B | E9: =IF(D9="A", INDEX(Matches!$E:$E, MATCH(A9, Matches!$A:$A, 0)), INDEX(Matches!$F:$F, MATCH(A9, Matches!$A:$A, 0))) -> 7 | F9: =IF(D9="A", INDEX(Matches!$F:$F, MATCH(A9, Matches!$A:$A, 0)), INDEX(Matches!$E:$E, MATCH(A9, Matches!$A:$A, 0))) -> 7 | G9: =IF(E9>F9,"Win",IF(E9<F9,"Loss","Draw")) -> Draw | H9: 0 | I9: 0 | K9: =A9&"_"&D9 -> 1_B
A10: 1 | B10: =VLOOKUP(A10,Matches!A:B,2,FALSE) -> 45974 | C10: Pranav | D10: B | E10: =IF(D10="A", INDEX(Matches!$E:$E, MATCH(A10, Matches!$A:$A, 0)), INDEX(Matches!$F:$F, MATCH(A10, Matches!$A:$A, 0))) -> 7 | F10: =IF(D10="A", INDEX(Matches!$F:$F, MATCH(A10, Matches!$A:$A, 0)), INDEX(Matches!$E:$E, MATCH(A10, Matches!$A:$A, 0))) -> 7 | G10: =IF(E10>F10,"Win",IF(E10<F10,"Loss","Draw")) -> Draw | H10: 3 | I10: 2 | K10: =A10&"_"&D10 -> 1_B
A11: 1 | B11: =VLOOKUP(A11,Matches!A:B,2,FALSE) -> 45974 | C11: Damian | D11: B | E11: =IF(D11="A", INDEX(Matches!$E:$E, MATCH(A11, Matches!$A:$A, 0)), INDEX(Matches!$F:$F, MATCH(A11, Matches!$A:$A, 0))) -> 7 | F11: =IF(D11="A", INDEX(Matches!$F:$F, MATCH(A11, Matches!$A:$A, 0)), INDEX(Matches!$E:$E, MATCH(A11, Matches!$A:$A, 0))) -> 7 | G11: =IF(E11>F11,"Win",IF(E11<F11,"Loss","Draw")) -> Draw | H11: 0 | I11: 0 | K11: =A11&"_"&D11 -> 1_B
A12: 2 | B12: =VLOOKUP(A12,Matches!A:B,2,FALSE) -> 45981 | C12: Sergio | D12: A | E12: =IF(D12="A", INDEX(Matches!$E:$E, MATCH(A12, Matches!$A:$A, 0)), INDEX(Matches!$F:$F, MATCH(A12, Matches!$A:$A, 0))) -> 5 | F12: =IF(D12="A", INDEX(Matches!$F:$F, MATCH(A12, Matches!$A:$A, 0)), INDEX(Matches!$E:$E, MATCH(A12, Matches!$A:$A, 0))) -> 7 | G12: =IF(E12>F12,"Win",IF(E12<F12,"Loss","Draw")) -> Loss | H12: 1 | I12: 0 | K12: =A12&"_"&D12 -> 2_A
A13: 2 | B13: =VLOOKUP(A13,Matches!A:B,2,FALSE) -> 45981 | C13: Musta | D13: A | E13: =IF(D13="A", INDEX(Matches!$E:$E, MATCH(A13, Matches!$A:$A, 0)), INDEX(Matches!$F:$F, MATCH(A13, Matches!$A:$A, 0))) -> 5 | F13: =IF(D13="A", INDEX(Matches!$F:$F, MATCH(A13, Matches!$A:$A, 0)), INDEX(Matches!$E:$E, MATCH(A13, Matches!$A:$A, 0))) -> 7 | G13: =IF(E13>F13,"Win",IF(E13<F13,"Loss","Draw")) -> Loss | H13: 1 | I13: 0 | K13: =A13&"_"&D13 -> 2_A
... A25: 2 | B25: =VLOOKUP(A25,Matches!A:B,2,FALSE) -> 45981 | C25: Alirio | D25: B | E25: =IF(D25="A", INDEX(Matches!$E:$E, MATCH(A25, Matches!$A:$A, 0)), INDEX(Matches!$F:$F, MATCH(A25, Matches!$A:$A, 0))) -> 7 | F25: =IF(D25="A", INDEX(Matches!$F:$F, MATCH(A25, Matches!$A:$A, 0)), INDEX(Matches!$E:$E, MATCH(A25, Matches!$A:$A, 0))) -> 5 | G25: =IF(E25>F25,"Win",IF(E25<F25,"Loss","Draw")) -> Win | H25: 0 | I25: 0 | K25: =A25&"_"&D25 -> 2_B
A26: 3 | B26: 45988 | C26: Sergio | D26: A | E26: =IF(D26="A", INDEX(Matches!$E:$E, MATCH(A26, Matches!$A:$A, 0)), INDEX(Matches!$F:$F, MATCH(A26, Matches!$A:$A, 0))) -> 7 | F26: =IF(D26="A", INDEX(Matches!$F:$F, MATCH(A26, Matches!$A:$A, 0)), INDEX(Matches!$E:$E, MATCH(A26, Matches!$A:$A, 0))) -> 9 | G26: =IF(E26>F26,"Win",IF(E26<F26,"Loss","Draw")) -> Loss | H26: 2 | I26: 1 | K26: =A26&"_"&D26 -> 3_A
A27: 3 | B27: 45988 | C27: Diego | D27: A | E27: =IF(D27="A", INDEX(Matches!$E:$E, MATCH(A27, Matches!$A:$A, 0)), INDEX(Matches!$F:$F, MATCH(A27, Matches!$A:$A, 0))) -> 7 | F27: =IF(D27="A", INDEX(Matches!$F:$F, MATCH(A27, Matches!$A:$A, 0)), INDEX(Matches!$E:$E, MATCH(A27, Matches!$A:$A, 0))) -> 9 | G27: =IF(E27>F27,"Win",IF(E27<F27,"Loss","Draw")) -> Loss | H27: 1 | I27: 0 | K27: =A27&"_"&D27 -> 3_A
A28: 3 | B28: 45988 | C28: Enrico | D28: A | E28: =IF(D28="A", INDEX(Matches!$E:$E, MATCH(A28, Matches!$A:$A, 0)), INDEX(Matches!$F:$F, MATCH(A28, Matches!$A:$A, 0))) -> 7 | F28: =IF(D28="A", INDEX(Matches!$F:$F, MATCH(A28, Matches!$A:$A, 0)), INDEX(Matches!$E:$E, MATCH(A28, Matches!$A:$A, 0))) -> 9 | G28: =IF(E28>F28,"Win",IF(E28<F28,"Loss","Draw")) -> Loss | H28: 4 | I28: 0 | K28: =A28&"_"&D28 -> 3_A
A29: 3 | B29: 45988 | C29: Lorenzo | D29: A | E29: =IF(D29="A", INDEX(Matches!$E:$E, MATCH(A29, Matches!$A:$A, 0)), INDEX(Matches!$F:$F, MATCH(A29, Matches!$A:$A, 0))) -> 7 | F29: =IF(D29="A", INDEX(Matches!$F:$F, MATCH(A29, Matches!$A:$A, 0)), INDEX(Matches!$E:$E, MATCH(A29, Matches!$A:$A, 0))) -> 9 | G29: =IF(E29>F29,"Win",IF(E29<F29,"Loss","Draw")) -> Loss | H29: 0 | I29: 1 | K29: =A29&"_"&D29 -> 3_A
A30: 3 | B30: 45988 | C30: Andreadb | D30: A | E30: =IF(D30="A", INDEX(Matches!$E:$E, MATCH(A30, Matches!$A:$A, 0)), INDEX(Matches!$F:$F, MATCH(A30, Matches!$A:$A, 0))) -> 7 | F30: =IF(D30="A", INDEX(Matches!$F:$F, MATCH(A30, Matches!$A:$A, 0)), INDEX(Matches!$E:$E, MATCH(A30, Matches!$A:$A, 0))) -> 9 | G30: =IF(E30>F30,"Win",IF(E30<F30,"Loss","Draw")) -> Loss | H30: 0 | I30: 2 | K30: =A30&"_"&D30 -> 3_A
A31: 3 | B31: 45988 | C31: Musta | D31: B | E31: =IF(D31="A", INDEX(Matches!$E:$E, MATCH(A31, Matches!$A:$A, 0)), INDEX(Matches!$F:$F, MATCH(A31, Matches!$A:$A, 0))) -> 9 | F31: =IF(D31="A", INDEX(Matches!$F:$F, MATCH(A31, Matches!$A:$A, 0)), INDEX(Matches!$E:$E, MATCH(A31, Matches!$A:$A, 0))) -> 7 | G31: =IF(E31>F31,"Win",IF(E31<F31,"Loss","Draw")) -> Win | H31: 3 | I31: 3 | K31: =A31&"_"&D31 -> 3_B
A32: 3 | B32: 45988 | C32: Jose | D32: B | E32: =IF(D32="A", INDEX(Matches!$E:$E, MATCH(A32, Matches!$A:$A, 0)), INDEX(Matches!$F:$F, MATCH(A32, Matches!$A:$A, 0))) -> 9 | F32: =IF(D32="A", INDEX(Matches!$F:$F, MATCH(A32, Matches!$A:$A, 0)), INDEX(Matches!$E:$E, MATCH(A32, Matches!$A:$A, 0))) -> 7 | G32: =IF(E32>F32,"Win",IF(E32<F32,"Loss","Draw")) -> Win | H32: 2 | I32: 1 | K32: =A32&"_"&D32 -> 3_B
A33: 3 | B33: 45988 | C33: Barroso | D33: B | E33: =IF(D33="A", INDEX(Matches!$E:$E, MATCH(A33, Matches!$A:$A, 0)), INDEX(Matches!$F:$F, MATCH(A33, Matches!$A:$A, 0))) -> 9 | F33: =IF(D33="A", INDEX(Matches!$F:$F, MATCH(A33, Matches!$A:$A, 0)), INDEX(Matches!$E:$E, MATCH(A33, Matches!$A:$A, 0))) -> 7 | G33: =IF(E33>F33,"Win",IF(E33<F33,"Loss","Draw")) -> Win | H33: 3 | I33: 1 | K33: =A33&"_"&D33 -> 3_B
A34: 3 | B34: 45988 | C34: Giacomo | D34: B | E34: =IF(D34="A", INDEX(Matches!$E:$E, MATCH(A34, Matches!$A:$A, 0)), INDEX(Matches!$F:$F, MATCH(A34, Matches!$A:$A, 0))) -> 9 | F34: =IF(D34="A", INDEX(Matches!$F:$F, MATCH(A34, Matches!$A:$A, 0)), INDEX(Matches!$E:$E, MATCH(A34, Matches!$A:$A, 0))) -> 7 | G34: =IF(E34>F34,"Win",IF(E34<F34,"Loss","Draw")) -> Win | H34: 1 | I34: 1 | K34: =A34&"_"&D34 -> 3_B
A35: 3 | B35: 45988 | C35: Dario | D35: B | E35: =IF(D35="A", INDEX(Matches!$E:$E, MATCH(A35, Matches!$A:$A, 0)), INDEX(Matches!$F:$F, MATCH(A35, Matches!$A:$A, 0))) -> 9 | F35: =IF(D35="A", INDEX(Matches!$F:$F, MATCH(A35, Matches!$A:$A, 0)), INDEX(Matches!$E:$E, MATCH(A35, Matches!$A:$A, 0))) -> 7 | G35: =IF(E35>F35,"Win",IF(E35<F35,"Loss","Draw")) -> Win | H35: 0 | I35: 1 | K35: =A35&"_"&D35 -> 3_B
A36: 4 | B36: 45995 | C36: Sergio | D36: A | E36: =IF(D36="A", INDEX(Matches!$E:$E, MATCH(A36, Matches!$A:$A, 0)), INDEX(Matches!$F:$F, MATCH(A36, Matches!$A:$A, 0))) -> 13 | F36: =IF(D36="A", INDEX(Matches!$F:$F, MATCH(A36, Matches!$A:$A, 0)), INDEX(Matches!$E:$E, MATCH(A36, Matches!$A:$A, 0))) -> 8 | G36: =IF(E36>F36,"Win",IF(E36<F36,"Loss","Draw")) -> Win | H36: 3 | I36: 3 | K36: =A36&"_"&D36 -> 4_A
A37: 4 | B37: 45995 | C37: Lorenzo | D37: A | E37: =IF(D37="A", INDEX(Matches!$E:$E, MATCH(A37, Matches!$A:$A, 0)), INDEX(Matches!$F:$F, MATCH(A37, Matches!$A:$A, 0))) -> 13 | F37: =IF(D37="A", INDEX(Matches!$F:$F, MATCH(A37, Matches!$A:$A, 0)), INDEX(Matches!$E:$E, MATCH(A37, Matches!$A:$A, 0))) -> 8 | G37: =IF(E37>F37,"Win",IF(E37<F37,"Loss","Draw")) -> Win | H37: 1 | I37: 2 | K37: =A37&"_"&D37 -> 4_A
... A59: 6 | B59: 46009 | C59: Karl | D59: A | E59: =IF(D59="A", INDEX(Matches!$E:$E, MATCH(A59, Matches!$A:$A, 0)), INDEX(Matches!$F:$F, MATCH(A59, Matches!$A:$A, 0))) -> 16 | F59: =IF(D59="A", INDEX(Matches!$F:$F, MATCH(A59, Matches!$A:$A, 0)), INDEX(Matches!$E:$E, MATCH(A59, Matches!$A:$A, 0))) -> 17 | G59: =IF(E59>F59,"Win",IF(E59<F59,"Loss","Draw")) -> Loss | H59: 1 | I59: 0 | K59: =A59&"_"&D59 -> 6_A
A60: 6 | B60: 46009 | C60: Barroso | D60: A | E60: =IF(D60="A", INDEX(Matches!$E:$E, MATCH(A60, Matches!$A:$A, 0)), INDEX(Matches!$F:$F, MATCH(A60, Matches!$A:$A, 0))) -> 16 | F60: =IF(D60="A", INDEX(Matches!$F:$F, MATCH(A60, Matches!$A:$A, 0)), INDEX(Matches!$E:$E, MATCH(A60, Matches!$A:$A, 0))) -> 17 | J60: Barroso played for both teams switching half way, so I put it only once in team B | K60: =A60&"_"&D60 -> 6_A
A61: 6 | B61: 46009 | C61: Stefano | D61: B | E61: =IF(D61="A", INDEX(Matches!$E:$E, MATCH(A61, Matches!$A:$A, 0)), INDEX(Matches!$F:$F, MATCH(A61, Matches!$A:$A, 0))) -> 17 | F61: =IF(D61="A", INDEX(Matches!$F:$F, MATCH(A61, Matches!$A:$A, 0)), INDEX(Matches!$E:$E, MATCH(A61, Matches!$A:$A, 0))) -> 16 | G61: =IF(E61>F61,"Win",IF(E61<F61,"Loss","Draw")) -> Win | H61: 8 | I61: 1 | K61: =A61&"_"&D61 -> 6_B
A62: 6 | B62: 46009 | C62: Musta | D62: B | E62: =IF(D62="A", INDEX(Matches!$E:$E, MATCH(A62, Matches!$A:$A, 0)), INDEX(Matches!$F:$F, MATCH(A62, Matches!$A:$A, 0))) -> 17 | F62: =IF(D62="A", INDEX(Matches!$F:$F, MATCH(A62, Matches!$A:$A, 0)), INDEX(Matches!$E:$E, MATCH(A62, Matches!$A:$A, 0))) -> 16 | G62: =IF(E62>F62,"Win",IF(E62<F62,"Loss","Draw")) -> Win | H62: 2 | I62: 3 | K62: =A62&"_"&D62 -> 6_B
A63: 6 | B63: 46009 | C63: Andreadb | D63: B | E63: =IF(D63="A", INDEX(Matches!$E:$E, MATCH(A63, Matches!$A:$A, 0)), INDEX(Matches!$F:$F, MATCH(A63, Matches!$A:$A, 0))) -> 17 | F63: =IF(D63="A", INDEX(Matches!$F:$F, MATCH(A63, Matches!$A:$A, 0)), INDEX(Matches!$E:$E, MATCH(A63, Matches!$A:$A, 0))) -> 16 | G63: =IF(E63>F63,"Win",IF(E63<F63,"Loss","Draw")) -> Win | H63: 0 | I63: 0 | K63: =A63&"_"&D63 -> 6_B
A64: 6 | B64: 46009 | C64: Julio | D64: B | E64: =IF(D64="A", INDEX(Matches!$E:$E, MATCH(A64, Matches!$A:$A, 0)), INDEX(Matches!$F:$F, MATCH(A64, Matches!$A:$A, 0))) -> 17 | F64: =IF(D64="A", INDEX(Matches!$F:$F, MATCH(A64, Matches!$A:$A, 0)), INDEX(Matches!$E:$E, MATCH(A64, Matches!$A:$A, 0))) -> 16 | G64: =IF(E64>F64,"Win",IF(E64<F64,"Loss","Draw")) -> Win | H64: 5 | I64: 1 | K64: =A64&"_"&D64 -> 6_B
A65: 6 | B65: 46009 | C65: Alirio | D65: B | E65: =IF(D65="A", INDEX(Matches!$E:$E, MATCH(A65, Matches!$A:$A, 0)), INDEX(Matches!$F:$F, MATCH(A65, Matches!$A:$A, 0))) -> 17 | F65: =IF(D65="A", INDEX(Matches!$F:$F, MATCH(A65, Matches!$A:$A, 0)), INDEX(Matches!$E:$E, MATCH(A65, Matches!$A:$A, 0))) -> 16 | G65: =IF(E65>F65,"Win",IF(E65<F65,"Loss","Draw")) -> Win | H65: 0 | I65: 0 | K65: =A65&"_"&D65 -> 6_B
A66: 6 | B66: 46009 | C66: Barroso | D66: B | E66: =IF(D66="A", INDEX(Matches!$E:$E, MATCH(A66, Matches!$A:$A, 0)), INDEX(Matches!$F:$F, MATCH(A66, Matches!$A:$A, 0))) -> 17 | F66: =IF(D66="A", INDEX(Matches!$F:$F, MATCH(A66, Matches!$A:$A, 0)), INDEX(Matches!$E:$E, MATCH(A66, Matches!$A:$A, 0))) -> 16 | G66: =IF(E66>F66,"Win",IF(E66<F66,"Loss","Draw")) -> Win | H66: 6 | I66: 4 | K66: =A66&"_"&D66 -> 6_B
A67: 7 | B67: 46030 | C67: Gioele | D67: A | E67: =IF(D67="A", INDEX(Matches!$E:$E, MATCH(A67, Matches!$A:$A, 0)), INDEX(Matches!$F:$F, MATCH(A67, Matches!$A:$A, 0))) -> 6 | F67: =IF(D67="A", INDEX(Matches!$F:$F, MATCH(A67, Matches!$A:$A, 0)), INDEX(Matches!$E:$E, MATCH(A67, Matches!$A:$A, 0))) -> 11 | G67: =IF(E67>F67,"Win",IF(E67<F67,"Loss","Draw")) -> Loss | H67: 2 | I67: 4 | K67: =A67&"_"&D67 -> 7_A
A68: 7 | B68: 46030 | C68: Alessandro C | D68: A | E68: =IF(D68="A", INDEX(Matches!$E:$E, MATCH(A68, Matches!$A:$A, 0)), INDEX(Matches!$F:$F, MATCH(A68, Matches!$A:$A, 0))) -> 6 | F68: =IF(D68="A", INDEX(Matches!$F:$F, MATCH(A68, Matches!$A:$A, 0)), INDEX(Matches!$E:$E, MATCH(A68, Matches!$A:$A, 0))) -> 11 | G68: =IF(E68>F68,"Win",IF(E68<F68,"Loss","Draw")) -> Loss | H68: 2 | I68: 0 | K68: =A68&"_"&D68 -> 7_A
A69: 7 | B69: 46030 | C69: Dario | D69: A | E69: =IF(D69="A", INDEX(Matches!$E:$E, MATCH(A69, Matches!$A:$A, 0)), INDEX(Matches!$F:$F, MATCH(A69, Matches!$A:$A, 0))) -> 6 | F69: =IF(D69="A", INDEX(Matches!$F:$F, MATCH(A69, Matches!$A:$A, 0)), INDEX(Matches!$E:$E, MATCH(A69, Matches!$A:$A, 0))) -> 11 | G69: =IF(E69>F69,"Win",IF(E69<F69,"Loss","Draw")) -> Loss | H69: 1 | I69: 1 | K69: =A69&"_"&D69 -> 7_A
A70: 7 | B70: 46030 | C70: Barroso | D70: A | E70: =IF(D70="A", INDEX(Matches!$E:$E, MATCH(A70, Matches!$A:$A, 0)), INDEX(Matches!$F:$F, MATCH(A70, Matches!$A:$A, 0))) -> 6 | F70: =IF(D70="A", INDEX(Matches!$F:$F, MATCH(A70, Matches!$A:$A, 0)), INDEX(Matches!$E:$E, MATCH(A70, Matches!$A:$A, 0))) -> 11 | G70: =IF(E70>F70,"Win",IF(E70<F70,"Loss","Draw")) -> Loss | H70: 2 | I70: 1 | K70: =A70&"_"&D70 -> 7_A
A71: 7 | B71: 46030 | C71: Enrico | D71: A | E71: =IF(D71="A", INDEX(Matches!$E:$E, MATCH(A71, Matches!$A:$A, 0)), INDEX(Matches!$F:$F, MATCH(A71, Matches!$A:$A, 0))) -> 6 | F71: =IF(D71="A", INDEX(Matches!$F:$F, MATCH(A71, Matches!$A:$A, 0)), INDEX(Matches!$E:$E, MATCH(A71, Matches!$A:$A, 0))) -> 11 | G71: =IF(E71>F71,"Win",IF(E71<F71,"Loss","Draw")) -> Loss | H71: 1 | I71: 0 | K71: =A71&"_"&D71 -> 7_A
A72: 7 | B72: 46030 | C72: Alessandro D | D72: B | E72: =IF(D72="A", INDEX(Matches!$E:$E, MATCH(A72, Matches!$A:$A, 0)), INDEX(Matches!$F:$F, MATCH(A72, Matches!$A:$A, 0))) -> 11 | F72: =IF(D72="A", INDEX(Matches!$F:$F, MATCH(A72, Matches!$A:$A, 0)), INDEX(Matches!$E:$E, MATCH(A72, Matches!$A:$A, 0))) -> 6 | G72: =IF(E72>F72,"Win",IF(E72<F72,"Loss","Draw")) -> Win | H72: 0 | I72: 1 | K72: =A72&"_"&D72 -> 7_B
...

Sheet Players
A1: Player Name | B1: Position | C1: Match Played | D1: Total Goals Scored | E1: Total Goals Conceded | F1: Goal Difference | G1: Games Won | H1: Games Drew | I1: Games Lost | J1: % Win | K1: Goal Scored | L1: Goal/Game | M1: Assists | N1: MVP | O1: MVP/Game | P1: Own Goals
A2: Pranav | C2: =COUNTIF('Team Lineups'!C:C,A2) -> 2 | D2: =SUMIF('Team Lineups'!C:C,A2,'Team Lineups'!E:E) -> 14 | E2: =SUMIF('Team Lineups'!C:C,A2,'Team Lineups'!F:F) -> 12 | F2: =D2-E2 -> 2 | G2: =COUNTIFS('Team Lineups'!C:C,A2,'Team Lineups'!G:G,"Win") -> 1 | H2: =COUNTIFS('Team Lineups'!C:C,A2,'Team Lineups'!G:G,"Draw") -> 1 | I2: =COUNTIFS('Team Lineups'!C:C,A2,'Team Lineups'!G:G,"Loss") -> 0 | J2: =G2/C2 -> 0.5 | K2: =SUMIF('Team Lineups'!C:C,A2,'Team Lineups'!H:H) -> 5 | L2: =K2/C2 -> 2.5 | M2: =SUMIF('Team Lineups'!C:C,A2,'Team Lineups'!I:I) -> 2 | N2: =COUNTIF(Matches!G:G,A2) -> 2 | O2: =N2/C2 -> 1 | P2: =SUMIF('Team Lineups'!C:C,A2,'Team Lineups'!J:J) -> 0
A3: Gianmarco | C3: =COUNTIF('Team Lineups'!C:C,A3) -> 7 | D3: =SUMIF('Team Lineups'!C:C,A3,'Team Lineups'!E:E) -> 37 | E3: =SUMIF('Team Lineups'!C:C,A3,'Team Lineups'!F:F) -> 38 | F3: =D3-E3 -> -1 | G3: =COUNTIFS('Team Lineups'!C:C,A3,'Team Lineups'!G:G,"Win") -> 3 | H3: =COUNTIFS('Team Lineups'!C:C,A3,'Team Lineups'!G:G,"Draw") -> 2 | I3: =COUNTIFS('Team Lineups'!C:C,A3,'Team Lineups'!G:G,"Loss") -> 2 | J3: =G3/C3 -> 0.42857143 | K3: =SUMIF('Team Lineups'!C:C,A3,'Team Lineups'!H:H) -> 4 | L3: =K3/C3 -> 0.57142857 | M3: =SUMIF('Team Lineups'!C:C,A3,'Team Lineups'!I:I) -> 3 | N3: =COUNTIF(Matches!G:G,A3) -> 0 | O3: =N3/C3 -> 0 | P3: =SUMIF('Team Lineups'!C:C,A3,'Team Lineups'!J:J) -> 0
A4: Alirio | C4: =COUNTIF('Team Lineups'!C:C,A4) -> 6 | D4: =SUMIF('Team Lineups'!C:C,A4,'Team Lineups'!E:E) -> 46 | E4: =SUMIF('Team Lineups'!C:C,A4,'Team Lineups'!F:F) -> 42 | F4: =D4-E4 -> 4 | G4: =COUNTIFS('Team Lineups'!C:C,A4,'Team Lineups'!G:G,"Win") -> 4 | H4: =COUNTIFS('Team Lineups'!C:C,A4,'Team Lineups'!G:G,"Draw") -> 0 | I4: =COUNTIFS('Team Lineups'!C:C,A4,'Team Lineups'!G:G,"Loss") -> 2 | J4: =G4/C4 -> 0.66666667 | K4: =SUMIF('Team Lineups'!C:C,A4,'Team Lineups'!H:H) -> 1 | L4: =K4/C4 -> 0.16666667 | M4: =SUMIF('Team Lineups'!C:C,A4,'Team Lineups'!I:I) -> 1 | N4: =COUNTIF(Matches!G:G,A4) -> 0 | O4: =N4/C4 -> 0 | P4: =SUMIF('Team Lineups'!C:C,A4,'Team Lineups'!J:J) -> 0
A5: Gioele | C5: =COUNTIF('Team Lineups'!C:C,A5) -> 8 | D5: =SUMIF('Team Lineups'!C:C,A5,'Team Lineups'!E:E) -> 43 | E5: =SUMIF('Team Lineups'!C:C,A5,'Team Lineups'!F:F) -> 59 | F5: =D5-E5 -> -16 | G5: =COUNTIFS('Team Lineups'!C:C,A5,'Team Lineups'!G:G,"Win") -> 0 | H5: =COUNTIFS('Team Lineups'!C:C,A5,'Team Lineups'!G:G,"Draw") -> 2 | I5: =COUNTIFS('Team Lineups'!C:C,A5,'Team Lineups'!G:G,"Loss") -> 6 | J5: =G5/C5 -> 0 | K5: =SUMIF('Team Lineups'!C:C,A5,'Team Lineups'!H:H) -> 11 | L5: =K5/C5 -> 1.375 | M5: =SUMIF('Team Lineups'!C:C,A5,'Team Lineups'!I:I) -> 8 | N5: =COUNTIF(Matches!G:G,A5) -> 0 | O5: =N5/C5 -> 0 | P5: =SUMIF('Team Lineups'!C:C,A5,'Team Lineups'!J:J) -> 0
A6: Angelo | C6: =COUNTIF('Team Lineups'!C:C,A6) -> 4 | D6: =SUMIF('Team Lineups'!C:C,A6,'Team Lineups'!E:E) -> 26 | E6: =SUMIF('Team Lineups'!C:C,A6,'Team Lineups'!F:F) -> 21 | F6: =D6-E6 -> 5 | G6: =COUNTIFS('Team Lineups'!C:C,A6,'Team Lineups'!G:G,"Win") -> 3 | H6: =COUNTIFS('Team Lineups'!C:C,A6,'Team Lineups'!G:G,"Draw") -> 1 | I6: =COUNTIFS('Team Lineups'!C:C,A6,'Team Lineups'!G:G,"Loss") -> 0 | J6: =G6/C6 -> 0.75 | K6: =SUMIF('Team Lineups'!C:C,A6,'Team Lineups'!H:H) -> 3 | L6: =K6/C6 -> 0.75 | M6: =SUMIF('Team Lineups'!C:C,A6,'Team Lineups'!I:I) -> 2 | N6: =COUNTIF(Matches!G:G,A6) -> 0 | O6: =N6/C6 -> 0 | P6: =SUMIF('Team Lineups'!C:C,A6,'Team Lineups'!J:J) -> 2
A7: Barroso | C7: =COUNTIF('Team Lineups'!C:C,A7) -> 12 | D7: =SUMIF('Team Lineups'!C:C,A7,'Team Lineups'!E:E) -> 92 | E7: =SUMIF('Team Lineups'!C:C,A7,'Team Lineups'!F:F) -> 105 | F7: =D7-E7 -> -13 | G7: =COUNTIFS('Team Lineups'!C:C,A7,'Team Lineups'!G:G,"Win") -> 3 | H7: =COUNTIFS('Team Lineups'!C:C,A7,'Team Lineups'!G:G,"Draw") -> 2 | I7: =COUNTIFS('Team Lineups'!C:C,A7,'Team Lineups'!G:G,"Loss") -> 6 | J7: =G7/C7 -> 0.25 | K7: =SUMIF('Team Lineups'!C:C,A7,'Team Lineups'!H:H) -> 17 | L7: =K7/C7 -> 1.4166667 | M7: =SUMIF('Team Lineups'!C:C,A7,'Team Lineups'!I:I) -> 11 | N7: =COUNTIF(Matches!G:G,A7) -> 0 | O7: =N7/C7 -> 0 | P7: =SUMIF('Team Lineups'!C:C,A7,'Team Lineups'!J:J) -> 0
A8: Musta | C8: =COUNTIF('Team Lineups'!C:C,A8) -> 11 | D8: =SUMIF('Team Lineups'!C:C,A8,'Team Lineups'!E:E) -> 86 | E8: =SUMIF('Team Lineups'!C:C,A8,'Team Lineups'!F:F) -> 72 | F8: =D8-E8 -> 14 | G8: =COUNTIFS('Team Lineups'!C:C,A8,'Team Lineups'!G:G,"Win") -> 6 | H8: =COUNTIFS('Team Lineups'!C:C,A8,'Team Lineups'!G:G,"Draw") -> 3 | I8: =COUNTIFS('Team Lineups'!C:C,A8,'Team Lineups'!G:G,"Loss") -> 2 | J8: =G8/C8 -> 0.54545455 | K8: =SUMIF('Team Lineups'!C:C,A8,'Team Lineups'!H:H) -> 26 | L8: =K8/C8 -> 2.3636364 | M8: =SUMIF('Team Lineups'!C:C,A8,'Team Lineups'!I:I) -> 14 | N8: =COUNTIF(Matches!G:G,A8) -> 2 | O8: =N8/C8 -> 0.18181818 | P8: =SUMIF('Team Lineups'!C:C,A8,'Team Lineups'!J:J) -> 0
A9: Dario | C9: =COUNTIF('Team Lineups'!C:C,A9) -> 8 | D9: =SUMIF('Team Lineups'!C:C,A9,'Team Lineups'!E:E) -> 43 | E9: =SUMIF('Team Lineups'!C:C,A9,'Team Lineups'!F:F) -> 49 | F9: =D9-E9 -> -6 | G9: =COUNTIFS('Team Lineups'!C:C,A9,'Team Lineups'!G:G,"Win") -> 2 | H9: =COUNTIFS('Team Lineups'!C:C,A9,'Team Lineups'!G:G,"Draw") -> 2 | I9: =COUNTIFS('Team Lineups'!C:C,A9,'Team Lineups'!G:G,"Loss") -> 4 | J9: =G9/C9 -> 0.25 | K9: =SUMIF('Team Lineups'!C:C,A9,'Team Lineups'!H:H) -> 4 | L9: =K9/C9 -> 0.5 | M9: =SUMIF('Team Lineups'!C:C,A9,'Team Lineups'!I:I) -> 3 | N9: =COUNTIF(Matches!G:G,A9) -> 1 | O9: =N9/C9 -> 0.125 | P9: =SUMIF('Team Lineups'!C:C,A9,'Team Lineups'!J:J) -> 0
A10: Diego | C10: =COUNTIF('Team Lineups'!C:C,A10) -> 6 | D10: =SUMIF('Team Lineups'!C:C,A10,'Team Lineups'!E:E) -> 35 | E10: =SUMIF('Team Lineups'!C:C,A10,'Team Lineups'!F:F) -> 32 | F10: =D10-E10 -> 3 | G10: =COUNTIFS('Team Lineups'!C:C,A10,'Team Lineups'!G:G,"Win") -> 3 | H10: =COUNTIFS('Team Lineups'!C:C,A10,'Team Lineups'!G:G,"Draw") -> 1 | I10: =COUNTIFS('Team Lineups'!C:C,A10,'Team Lineups'!G:G,"Loss") -> 2 | J10: =G10/C10 -> 0.5 | K10: =SUMIF('Team Lineups'!C:C,A10,'Team Lineups'!H:H) -> 7 | L10: =K10/C10 -> 1.1666667 | M10: =SUMIF('Team Lineups'!C:C,A10,'Team Lineups'!I:I) -> 7 | N10: =COUNTIF(Matches!G:G,A10) -> 1 | O10: =N10/C10 -> 0.16666667 | P10: =SUMIF('Team Lineups'!C:C,A10,'Team Lineups'!J:J) -> 0
A11: Edison | C11: =COUNTIF('Team Lineups'!C:C,A11) -> 0 | D11: =SUMIF('Team Lineups'!C:C,A11,'Team Lineups'!E:E) -> 0 | E11: =SUMIF('Team Lineups'!C:C,A11,'Team Lineups'!F:F) -> 0 | F11: =D11-E11 -> 0 | G11: =COUNTIFS('Team Lineups'!C:C,A11,'Team Lineups'!G:G,"Win") -> 0 | H11: =COUNTIFS('Team Lineups'!C:C,A11,'Team Lineups'!G:G,"Draw") -> 0 | I11: =COUNTIFS('Team Lineups'!C:C,A11,'Team Lineups'!G:G,"Loss") -> 0 | J11: =G11/C11 -> #DIV/0! | K11: =SUMIF('Team Lineups'!C:C,A11,'Team Lineups'!H:H) -> 0 | L11: =K11/C11 -> #DIV/0! | M11: =SUMIF('Team Lineups'!C:C,A11,'Team Lineups'!I:I) -> 0 | N11: =COUNTIF(Matches!G:G,A11) -> 0 | O11: =N11/C11 -> #DIV/0! | P11: =SUMIF('Team Lineups'!C:C,A11,'Team Lineups'!J:J) -> 0
A12: Enrico | C12: =COUNTIF('Team Lineups'!C:C,A12) -> 9 | D12: =SUMIF('Team Lineups'!C:C,A12,'Team Lineups'!E:E) -> 66 | E12: =SUMIF('Team Lineups'!C:C,A12,'Team Lineups'!F:F) -> 72 | F12: =D12-E12 -> -6 | G12: =COUNTIFS('Team Lineups'!C:C,A12,'Team Lineups'!G:G,"Win") -> 3 | H12: =COUNTIFS('Team Lineups'!C:C,A12,'Team Lineups'!G:G,"Draw") -> 0 | I12: =COUNTIFS('Team Lineups'!C:C,A12,'Team Lineups'!G:G,"Loss") -> 6 | J12: =G12/C12 -> 0.33333333 | K12: =SUMIF('Team Lineups'!C:C,A12,'Team Lineups'!H:H) -> 17 | L12: =K12/C12 -> 1.8888889 | M12: =SUMIF('Team Lineups'!C:C,A12,'Team Lineups'!I:I) -> 6 | N12: =COUNTIF(Matches!G:G,A12) -> 1 | O12: =N12/C12 -> 0.11111111 | P12: =SUMIF('Team Lineups'!C:C,A12,'Team Lineups'!J:J) -> 0
A13: Ervin | C13: =COUNTIF('Team Lineups'!C:C,A13) -> 0 | D13: =SUMIF('Team Lineups'!C:C,A13,'Team Lineups'!E:E) -> 0 | E13: =SUMIF('Team Lineups'!C:C,A13,'Team Lineups'!F:F) -> 0 | F13: =D13-E13 -> 0 | G13: =COUNTIFS('Team Lineups'!C:C,A13,'Team Lineups'!G:G,"Win") -> 0 | H13: =COUNTIFS('Team Lineups'!C:C,A13,'Team Lineups'!G:G,"Draw") -> 0 | I13: =COUNTIFS('Team Lineups'!C:C,A13,'Team Lineups'!G:G,"Loss") -> 0 | J13: =G13/C13 -> #DIV/0! | K13: =SUMIF('Team Lineups'!C:C,A13,'Team Lineups'!H:H) -> 0 | L13: =K13/C13 -> #DIV/0! | M13: =SUMIF('Team Lineups'!C:C,A13,'Team Lineups'!I:I) -> 0 | N13: =COUNTIF(Matches!G:G,A13) -> 0 | O13: =N13/C13 -> #DIV/0! | P13: =SUMIF('Team Lineups'!C:C,A13,'Team Lineups'!J:J) -> 0
... A36: Neil | C36: =COUNTIF('Team Lineups'!C:C,A36) -> 1 | D36: =SUMIF('Team Lineups'!C:C,A36,'Team Lineups'!E:E) -> 6 | E36: =SUMIF('Team Lineups'!C:C,A36,'Team Lineups'!F:F) -> 6 | F36: =D36-E36 -> 0 | G36: =COUNTIFS('Team Lineups'!C:C,A36,'Team Lineups'!G:G,"Win") -> 0 | H36: =COUNTIFS('Team Lineups'!C:C,A36,'Team Lineups'!G:G,"Draw") -> 1 | I36: =COUNTIFS('Team Lineups'!C:C,A36,'Team Lineups'!G:G,"Loss") -> 0 | J36: =G36/C36 -> 0 | K36: =SUMIF('Team Lineups'!C:C,A36,'Team Lineups'!H:H) -> 3 | L36: =K36/C36 -> 3 | M36: =SUMIF('Team Lineups'!C:C,A36,'Team Lineups'!I:I) -> 0 | N36: =COUNTIF(Matches!G:G,A36) -> 0 | O36: =N36/C36 -> 0 | P36: =SUMIF('Team Lineups'!C:C,A36,'Team Lineups'!J:J) -> 0

Sheet Sheet2
B1: {=TRANSPOSE(A2:A100)} -> Gioele | C1: Gianmarco | D1: Musta | E1: Alessandro D | F1: Andreadb | G1: Jose | H1: Alessandro C | I1: Lorenzo | J1: Pranav | K1: Damian | L1: Sergio | M1: Barroso | N1: Dario | O1: Tano | P1: Julio | Q1: Enrico | R1: Alirio | S1: Diego | T1: Giacomo | U1: Christian | V1: Karl | W1: Alberto | X1: Noah | Y1: TK | Z1: Manfredi | AA1: Stefano | AB1: Angelo | AC1: Tiago | AD1: Andrea M | AE1: Giosué | AF1: Neil | AG1: 0 | AH1: 0 | AI1: 0 | AJ1: 0 | AK1: 0 | AL1: 0 | AM1: 0 | AN1: 0 | AO1: 0 | AP1: 0 | AQ1: 0 | AR1: 0 | AS1: 0 | AT1: 0 | AU1: 0 | AV1: 0 | AW1: 0 | AX1: 0 | AY1: 0 | AZ1: 0 | BA1: 0 | BB1: 0 | BC1: 0 | BD1: 0 | BE1: 0 | BF1: 0 | BG1: 0 | BH1: 0 | BI1: 0 | BJ1: 0 | BK1: 0 | BL1: 0 | BM1: 0 | BN1: 0 | BO1: 0 | BP1: 0 | BQ1: 0 | BR1: 0 | BS1: 0 | BT1: 0 | BU1: 0 | BV1: 0 | BW1: 0 | BX1: 0 | BY1: 0 | BZ1: 0 | CA1: 0 | CB1: 0 | CC1: 0 | CD1: 0 | CE1: 0 | CF1: 0 | CG1: 0 | CH1: 0 | CI1: 0 | CJ1: 0 | CK1: 0 | CL1: 0 | CM1: 0 | CN1: 0 | CO1: 0 | CP1: 0 | CQ1: 0 | CR1: 0 | CS1: 0 | CT1: 0 | CU1: 0 | CV1: 0
A2: {=_xlfn.UNIQUE('Team Lineups'!C2:C500)} -> Gioele | B2: NA | C2: {=SUMPRODUCT(('Team Lineups'!$K$2:$K$2000<>"")*('Team Lineups'!$C$2:$C$2000=$A2)*COUNTIFS('Team Lineups'!$K$2:$K$2000,'Team Lineups'!$K$2:$K$2000,'Team Lineups'!$C$2:$C$2000,C$1))} -> 4 | D2: {=SUMPRODUCT(('Team Lineups'!$K$2:$K$2000<>"")*('Team Lineups'!$C$2:$C$2000=$A2)*COUNTIFS('Team Lineups'!$K$2:$K$2000,'Team Lineups'!$K$2:$K$2000,'Team Lineups'!$C$2:$C$2000,D$1))} -> 3 | E2: {=SUMPRODUCT(('Team Lineups'!$K$2:$K$2000<>"")*('Team Lineups'!$C$2:$C$2000=$A2)*COUNTIFS('Team Lineups'!$K$2:$K$2000,'Team Lineups'!$K$2:$K$2000,'Team Lineups'!$C$2:$C$2000,E$1))} -> 4 | F2: {=SUMPRODUCT(('Team Lineups'!$K$2:$K$2000<>"")*('Team Lineups'!$C$2:$C$2000=$A2)*COUNTIFS('Team Lineups'!$K$2:$K$2000,'Team Lineups'!$K$2:$K$2000,'Team Lineups'!$C$2:$C$2000,F$1))} -> 2 | G2: {=SUMPRODUCT(('Team Lineups'!$K$2:$K$2000<>"")*('Team Lineups'!$C$2:$C$2000=$A2)*COUNTIFS('Team Lineups'!$K$2:$K$2000,'Team Lineups'!$K$2:$K$2000,'Team Lineups'!$C$2:$C$2000,G$1))} -> 2 | H2: {=SUMPRODUCT(('Team Lineups'!$K$2:$K$2000<>"")*('Team Lineups'!$C$2:$C$2000=$A2)*COUNTIFS('Team Lineups'!$K$2:$K$2000,'Team Lineups'!$K$2:$K$2000,'Team Lineups'!$C$2:$C$2000,H$1))} -> 3 | I2: {=SUMPRODUCT(('Team Lineups'!$K$2:$K$2000<>"")*('Team Lineups'!$C$2:$C$2000=$A2)*COUNTIFS('Team Lineups'!$K$2:$K$2000,'Team Lineups'!$K$2:$K$2000,'Team Lineups'!$C$2:$C$2000,I$1))} -> 3 | J2: {=SUMPRODUCT(('Team Lineups'!$K$2:$K$2000<>"")*('Team Lineups'!$C$2:$C$2000=$A2)*COUNTIFS('Team Lineups'!$K$2:$K$2000,'Team Lineups'!$K$2:$K$2000,'Team Lineups'!$C$2:$C$2000,J$1))} -> 0 | ... AF2: {=SUMPRODUCT(('Team Lineups'!$K$2:$K$2000<>"")*('Team Lineups'!$C$2:$C$2000=$A2)*COUNTIFS('Team Lineups'!$K$2:$K$2000,'Team Lineups'!$K$2:$K$2000,'Team Lineups'!$C$2:$C$2000,AF$1))} -> 0
A3: Gianmarco | B3: {=SUMPRODUCT(('Team Lineups'!$K$2:$K$2000<>"")*('Team Lineups'!$C$2:$C$2000=$A3)*COUNTIFS('Team Lineups'!$K$2:$K$2000,'Team Lineups'!$K$2:$K$2000,'Team Lineups'!$C$2:$C$2000,B$1))} -> 4 | C3: NA | D3: {=SUMPRODUCT(('Team Lineups'!$K$2:$K$2000<>"")*('Team Lineups'!$C$2:$C$2000=$A3)*COUNTIFS('Team Lineups'!$K$2:$K$2000,'Team Lineups'!$K$2:$K$2000,'Team Lineups'!$C$2:$C$2000,D$1))} -> 4 | E3: {=SUMPRODUCT(('Team Lineups'!$K$2:$K$2000<>"")*('Team Lineups'!$C$2:$C$2000=$A3)*COUNTIFS('Team Lineups'!$K$2:$K$2000,'Team Lineups'!$K$2:$K$2000,'Team Lineups'!$C$2:$C$2000,E$1))} -> 5 | F3: {=SUMPRODUCT(('Team Lineups'!$K$2:$K$2000<>"")*('Team Lineups'!$C$2:$C$2000=$A3)*COUNTIFS('Team Lineups'!$K$2:$K$2000,'Team Lineups'!$K$2:$K$2000,'Team Lineups'!$C$2:$C$2000,F$1))} -> 2 | G3: {=SUMPRODUCT(('Team Lineups'!$K$2:$K$2000<>"")*('Team Lineups'!$C$2:$C$2000=$A3)*COUNTIFS('Team Lineups'!$K$2:$K$2000,'Team Lineups'!$K$2:$K$2000,'Team Lineups'!$C$2:$C$2000,G$1))} -> 2 | H3: {=SUMPRODUCT(('Team Lineups'!$K$2:$K$2000<>"")*('Team Lineups'!$C$2:$C$2000=$A3)*COUNTIFS('Team Lineups'!$K$2:$K$2000,'Team Lineups'!$K$2:$K$2000,'Team Lineups'!$C$2:$C$2000,H$1))} -> 2 | I3: {=SUMPRODUCT(('Team Lineups'!$K$2:$K$2000<>"")*('Team Lineups'!$C$2:$C$2000=$A3)*COUNTIFS('Team Lineups'!$K$2:$K$2000,'Team Lineups'!$K$2:$K$2000,'Team Lineups'!$C$2:$C$2000,I$1))} -> 2 | J3: {=SUMPRODUCT(('Team Lineups'!$K$2:$K$2000<>"")*('Team Lineups'!$C$2:$C$2000=$A3)*COUNTIFS('Team Lineups'!$K$2:$K$2000,'Team Lineups'!$K$2:$K$2000,'Team Lineups'!$C$2:$C$2000,J$1))} -> 0 | K3: {=SUMPRODUCT(('Team Lineups'!$K$2:$K$2000<>"")*('Team Lineups'!$C$2:$C$2000=$A3)*COUNTIFS('Team Lineups'!$K$2:$K$2000,'Team Lineups'!$K$2:$K$2000,'Team Lineups'!$C$2:$C$2000,K$1))} -> 0 | ... AF3: {=SUMPRODUCT(('Team Lineups'!$K$2:$K$2000<>"")*('Team Lineups'!$C$2:$C$2000=$A3)*COUNTIFS('Team Lineups'!$K$2:$K$2000,'Team Lineups'!$K$2:$K$2000,'Team Lineups'!$C$2:$C$2000,AF$1))} -> 0
A4: Musta | B4: {=SUMPRODUCT(('Team Lineups'!$K$2:$K$2000<>"")*('Team Lineups'!$C$2:$C$2000=$A4)*COUNTIFS('Team Lineups'!$K$2:$K$2000,'Team Lineups'!$K$2:$K$2000,'Team Lineups'!$C$2:$C$2000,B$1))} -> 3 | C4: {=SUMPRODUCT(('Team Lineups'!$K$2:$K$2000<>"")*('Team Lineups'!$C$2:$C$2000=$A4)*COUNTIFS('Team Lineups'!$K$2:$K$2000,'Team Lineups'!$K$2:$K$2000,'Team Lineups'!$C$2:$C$2000,C$1))} -> 4 | D4: NA | E4: {=SUMPRODUCT(('Team Lineups'!$K$2:$K$2000<>"")*('Team Lineups'!$C$2:$C$2000=$A4)*COUNTIFS('Team Lineups'!$K$2:$K$2000,'Team Lineups'!$K$2:$K$2000,'Team Lineups'!$C$2:$C$2000,E$1))} -> 5 | F4: {=SUMPRODUCT(('Team Lineups'!$K$2:$K$2000<>"")*('Team Lineups'!$C$2:$C$2000=$A4)*COUNTIFS('Team Lineups'!$K$2:$K$2000,'Team Lineups'!$K$2:$K$2000,'Team Lineups'!$C$2:$C$2000,F$1))} -> 6 | G4: {=SUMPRODUCT(('Team Lineups'!$K$2:$K$2000<>"")*('Team Lineups'!$C$2:$C$2000=$A4)*COUNTIFS('Team Lineups'!$K$2:$K$2000,'Team Lineups'!$K$2:$K$2000,'Team Lineups'!$C$2:$C$2000,G$1))} -> 1 | H4: {=SUMPRODUCT(('Team Lineups'!$K$2:$K$2000<>"")*('Team Lineups'!$C$2:$C$2000=$A4)*COUNTIFS('Team Lineups'!$K$2:$K$2000,'Team Lineups'!$K$2:$K$2000,'Team Lineups'!$C$2:$C$2000,H$1))} -> 2 | I4: {=SUMPRODUCT(('Team Lineups'!$K$2:$K$2000<>"")*('Team Lineups'!$C$2:$C$2000=$A4)*COUNTIFS('Team Lineups'!$K$2:$K$2000,'Team Lineups'!$K$2:$K$2000,'Team Lineups'!$C$2:$C$2000,I$1))} -> 4 | J4: {=SUMPRODUCT(('Team Lineups'!$K$2:$K$2000<>"")*('Team Lineups'!$C$2:$C$2000=$A4)*COUNTIFS('Team Lineups'!$K$2:$K$2000,'Team Lineups'!$K$2:$K$2000,'Team Lineups'!$C$2:$C$2000,J$1))} -> 0 | K4: {=SUMPRODUCT(('Team Lineups'!$K$2:$K$2000<>"")*('Team Lineups'!$C$2:$C$2000=$A4)*COUNTIFS('Team Lineups'!$K$2:$K$2000,'Team Lineups'!$K$2:$K$2000,'Team Lineups'!$C$2:$C$2000,K$1))} -> 0 | L4: {=SUMPRODUCT(('Team Lineups'!$K$2:$K$2000<>"")*('Team Lineups'!$C$2:$C$2000=$A4)*COUNTIFS('Team Lineups'!$K$2:$K$2000,'Team Lineups'!$K$2:$K$2000,'Team Lineups'!$C$2:$C$2000,L$1))} -> 6 | ... AF4: {=SUMPRODUCT(('Team Lineups'!$K$2:$K$2000<>"")*('Team Lineups'!$C$2:$C$2000=$A4)*COUNTIFS('Team Lineups'!$K$2:$K$2000,'Team Lineups'!$K$2:$K$2000,'Team Lineups'!$C$2:$C$2000,AF$1))} -> 0
A5: Alessandro D | B5: {=SUMPRODUCT(('Team Lineups'!$K$2:$K$2000<>"")*('Team Lineups'!$C$2:$C$2000=$A5)*COUNTIFS('Team Lineups'!$K$2:$K$2000,'Team Lineups'!$K$2:$K$2000,'Team Lineups'!$C$2:$C$2000,B$1))} -> 4 | C5: {=SUMPRODUCT(('Team Lineups'!$K$2:$K$2000<>"")*('Team Lineups'!$C$2:$C$2000=$A5)*COUNTIFS('Team Lineups'!$K$2:$K$2000,'Team Lineups'!$K$2:$K$2000,'Team Lineups'!$C$2:$C$2000,C$1))} -> 5 | D5: {=SUMPRODUCT(('Team Lineups'!$K$2:$K$2000<>"")*('Team Lineups'!$C$2:$C$2000=$A5)*COUNTIFS('Team Lineups'!$K$2:$K$2000,'Team Lineups'!$K$2:$K$2000,'Team Lineups'!$C$2:$C$2000,D$1))} -> 5 | E5: NA | F5: {=SUMPRODUCT(('Team Lineups'!$K$2:$K$2000<>"")*('Team Lineups'!$C$2:$C$2000=$A5)*COUNTIFS('Team Lineups'!$K$2:$K$2000,'Team Lineups'!$K$2:$K$2000,'Team Lineups'!$C$2:$C$2000,F$1))} -> 5 | G5: {=SUMPRODUCT(('Team Lineups'!$K$2:$K$2000<>"")*('Team Lineups'!$C$2:$C$2000=$A5)*COUNTIFS('Team Lineups'!$K$2:$K$2000,'Team Lineups'!$K$2:$K$2000,'Team Lineups'!$C$2:$C$2000,G$1))} -> 3 | H5: {=SUMPRODUCT(('Team Lineups'!$K$2:$K$2000<>"")*('Team Lineups'!$C$2:$C$2000=$A5)*COUNTIFS('Team Lineups'!$K$2:$K$2000,'Team Lineups'!$K$2:$K$2000,'Team Lineups'!$C$2:$C$2000,H$1))} -> 0 | I5: {=SUMPRODUCT(('Team Lineups'!$K$2:$K$2000<>"")*('Team Lineups'!$C$2:$C$2000=$A5)*COUNTIFS('Team Lineups'!$K$2:$K$2000,'Team Lineups'!$K$2:$K$2000,'Team Lineups'!$C$2:$C$2000,I$1))} -> 2 | J5: {=SUMPRODUCT(('Team Lineups'!$K$2:$K$2000<>"")*('Team Lineups'!$C$2:$C$2000=$A5)*COUNTIFS('Team Lineups'!$K$2:$K$2000,'Team Lineups'!$K$2:$K$2000,'Team Lineups'!$C$2:$C$2000,J$1))} -> 0 | K5: {=SUMPRODUCT(('Team Lineups'!$K$2:$K$2000<>"")*('Team Lineups'!$C$2:$C$2000=$A5)*COUNTIFS('Team Lineups'!$K$2:$K$2000,'Team Lineups'!$K$2:$K$2000,'Team Lineups'!$C$2:$C$2000,K$1))} -> 0 | L5: {=SUMPRODUCT(('Team Lineups'!$K$2:$K$2000<>"")*('Team Lineups'!$C$2:$C$2000=$A5)*COUNTIFS('Team Lineups'!$K$2:$K$2000,'Team Lineups'!$K$2:$K$2000,'Team Lineups'!$C$2:$C$2000,L$1))} -> 5 | M5: {=SUMPRODUCT(('Team Lineups'!$K$2:$K$2000<>"")*('Team Lineups'!$C$2:$C$2000=$A5)*COUNTIFS('Team Lineups'!$K$2:$K$2000,'Team Lineups'!$K$2:$K$2000,'Team Lineups'!$C$2:$C$2000,M$1))} -> 2 | ... AF5: {=SUMPRODUCT(('Team Lineups'!$K$2:$K$2000<>"")*('Team Lineups'!$C$2:$C$2000=$A5)*COUNTIFS('Team Lineups'!$K$2:$K$2000,'Team Lineups'!$K$2:$K$2000,'Team Lineups'!$C$2:$C$2000,AF$1))} -> 0
A6: Andreadb | B6: {=SUMPRODUCT(('Team Lineups'!$K$2:$K$2000<>"")*('Team Lineups'!$C$2:$C$2000=$A6)*COUNTIFS('Team Lineups'!$K$2:$K$2000,'Team Lineups'!$K$2:$K$2000,'Team Lineups'!$C$2:$C$2000,B$1))} -> 2 | C6: {=SUMPRODUCT(('Team Lineups'!$K$2:$K$2000<>"")*('Team Lineups'!$C$2:$C$2000=$A6)*COUNTIFS('Team Lineups'!$K$2:$K$2000,'Team Lineups'!$K$2:$K$2000,'Team Lineups'!$C$2:$C$2000,C$1))} -> 2 | D6: {=SUMPRODUCT(('Team Lineups'!$K$2:$K$2000<>"")*('Team Lineups'!$C$2:$C$2000=$A6)*COUNTIFS('Team Lineups'!$K$2:$K$2000,'Team Lineups'!$K$2:$K$2000,'Team Lineups'!$C$2:$C$2000,D$1))} -> 6 | E6: {=SUMPRODUCT(('Team Lineups'!$K$2:$K$2000<>"")*('Team Lineups'!$C$2:$C$2000=$A6)*COUNTIFS('Team Lineups'!$K$2:$K$2000,'Team Lineups'!$K$2:$K$2000,'Team Lineups'!$C$2:$C$2000,E$1))} -> 5 | F6: NA | G6: {=SUMPRODUCT(('Team Lineups'!$K$2:$K$2000<>"")*('Team Lineups'!$C$2:$C$2000=$A6)*COUNTIFS('Team Lineups'!$K$2:$K$2000,'Team Lineups'!$K$2:$K$2000,'Team Lineups'!$C$2:$C$2000,G$1))} -> 1 | H6: {=SUMPRODUCT(('Team Lineups'!$K$2:$K$2000<>"")*('Team Lineups'!$C$2:$C$2000=$A6)*COUNTIFS('Team Lineups'!$K$2:$K$2000,'Team Lineups'!$K$2:$K$2000,'Team Lineups'!$C$2:$C$2000,H$1))} -> 2 | I6: {=SUMPRODUCT(('Team Lineups'!$K$2:$K$2000<>"")*('Team Lineups'!$C$2:$C$2000=$A6)*COUNTIFS('Team Lineups'!$K$2:$K$2000,'Team Lineups'!$K$2:$K$2000,'Team Lineups'!$C$2:$C$2000,I$1))} -> 4 | J6: {=SUMPRODUCT(('Team Lineups'!$K$2:$K$2000<>"")*('Team Lineups'!$C$2:$C$2000=$A6)*COUNTIFS('Team Lineups'!$K$2:$K$2000,'Team Lineups'!$K$2:$K$2000,'Team Lineups'!$C$2:$C$2000,J$1))} -> 0 | K6: {=SUMPRODUCT(('Team Lineups'!$K$2:$K$2000<>"")*('Team Lineups'!$C$2:$C$2000=$A6)*COUNTIFS('Team Lineups'!$K$2:$K$2000,'Team Lineups'!$K$2:$K$2000,'Team Lineups'!$C$2:$C$2000,K$1))} -> 0 | L6: {=SUMPRODUCT(('Team Lineups'!$K$2:$K$2000<>"")*('Team Lineups'!$C$2:$C$2000=$A6)*COUNTIFS('Team Lineups'!$K$2:$K$2000,'Team Lineups'!$K$2:$K$2000,'Team Lineups'!$C$2:$C$2000,L$1))} -> 5 | M6: {=SUMPRODUCT(('Team Lineups'!$K$2:$K$2000<>"")*('Team Lineups'!$C$2:$C$2000=$A6)*COUNTIFS('Team Lineups'!$K$2:$K$2000,'Team Lineups'!$K$2:$K$2000,'Team Lineups'!$C$2:$C$2000,M$1))} -> 6 | N6: {=SUMPRODUCT(('Team Lineups'!$K$2:$K$2000<>"")*('Team Lineups'!$C$2:$C$2000=$A6)*COUNTIFS('Team Lineups'!$K$2:$K$2000,'Team Lineups'!$K$2:$K$2000,'Team Lineups'!$C$2:$C$2000,N$1))} -> 1 | ... AF6: {=SUMPRODUCT(('Team Lineups'!$K$2:$K$2000<>"")*('Team Lineups'!$C$2:$C$2000=$A6)*COUNTIFS('Team Lineups'!$K$2:$K$2000,'Team Lineups'!$K$2:$K$2000,'Team Lineups'!$C$2:$C$2000,AF$1))} -> 0
A7: Jose | B7: {=SUMPRODUCT(('Team Lineups'!$K$2:$K$2000<>"")*('Team Lineups'!$C$2:$C$2000=$A7)*COUNTIFS('Team Lineups'!$K$2:$K$2000,'Team Lineups'!$K$2:$K$2000,'Team Lineups'!$C$2:$C$2000,B$1))} -> 2 | C7: {=SUMPRODUCT(('Team Lineups'!$K$2:$K$2000<>"")*('Team Lineups'!$C$2:$C$2000=$A7)*COUNTIFS('Team Lineups'!$K$2:$K$2000,'Team Lineups'!$K$2:$K$2000,'Team Lineups'!$C$2:$C$2000,C$1))} -> 2 | D7: {=SUMPRODUCT(('Team Lineups'!$K$2:$K$2000<>"")*('Team Lineups'!$C$2:$C$2000=$A7)*COUNTIFS('Team Lineups'!$K$2:$K$2000,'Team Lineups'!$K$2:$K$2000,'Team Lineups'!$C$2:$C$2000,D$1))} -> 1 | E7: {=SUMPRODUCT(('Team Lineups'!$K$2:$K$2000<>"")*('Team Lineups'!$C$2:$C$2000=$A7)*COUNTIFS('Team Lineups'!$K$2:$K$2000,'Team Lineups'!$K$2:$K$2000,'Team Lineups'!$C$2:$C$2000,E$1))} -> 3 | F7: {=SUMPRODUCT(('Team Lineups'!$K$2:$K$2000<>"")*('Team Lineups'!$C$2:$C$2000=$A7)*COUNTIFS('Team Lineups'!$K$2:$K$2000,'Team Lineups'!$K$2:$K$2000,'Team Lineups'!$C$2:$C$2000,F$1))} -> 1 | G7: NA | H7: {=SUMPRODUCT(('Team Lineups'!$K$2:$K$2000<>"")*('Team Lineups'!$C$2:$C$2000=$A7)*COUNTIFS('Team Lineups'!$K$2:$K$2000,'Team Lineups'!$K$2:$K$2000,'Team Lineups'!$C$2:$C$2000,H$1))} -> 4 | I7: {=SUMPRODUCT(('Team Lineups'!$K$2:$K$2000<>"")*('Team Lineups'!$C$2:$C$2000=$A7)*COUNTIFS('Team Lineups'!$K$2:$K$2000,'Team Lineups'!$K$2:$K$2000,'Team Lineups'!$C$2:$C$2000,I$1))} -> 5 | J7: {=SUMPRODUCT(('Team Lineups'!$K$2:$K$2000<>"")*('Team Lineups'!$C$2:$C$2000=$A7)*COUNTIFS('Team Lineups'!$K$2:$K$2000,'Team Lineups'!$K$2:$K$2000,'Team Lineups'!$C$2:$C$2000,J$1))} -> 2 | K7: {=SUMPRODUCT(('Team Lineups'!$K$2:$K$2000<>"")*('Team Lineups'!$C$2:$C$2000=$A7)*COUNTIFS('Team Lineups'!$K$2:$K$2000,'Team Lineups'!$K$2:$K$2000,'Team Lineups'!$C$2:$C$2000,K$1))} -> 1 | L7: {=SUMPRODUCT(('Team Lineups'!$K$2:$K$2000<>"")*('Team Lineups'!$C$2:$C$2000=$A7)*COUNTIFS('Team Lineups'!$K$2:$K$2000,'Team Lineups'!$K$2:$K$2000,'Team Lineups'!$C$2:$C$2000,L$1))} -> 3 | M7: {=SUMPRODUCT(('Team Lineups'!$K$2:$K$2000<>"")*('Team Lineups'!$C$2:$C$2000=$A7)*COUNTIFS('Team Lineups'!$K$2:$K$2000,'Team Lineups'!$K$2:$K$2000,'Team Lineups'!$C$2:$C$2000,M$1))} -> 6 | N7: {=SUMPRODUCT(('Team Lineups'!$K$2:$K$2000<>"")*('Team Lineups'!$C$2:$C$2000=$A7)*COUNTIFS('Team Lineups'!$K$2:$K$2000,'Team Lineups'!$K$2:$K$2000,'Team Lineups'!$C$2:$C$2000,N$1))} -> 3 | O7: {=SUMPRODUCT(('Team Lineups'!$K$2:$K$2000<>"")*('Team Lineups'!$C$2:$C$2000=$A7)*COUNTIFS('Team Lineups'!$K$2:$K$2000,'Team Lineups'!$K$2:$K$2000,'Team Lineups'!$C$2:$C$2000,O$1))} -> 0 | ... AF7: {=SUMPRODUCT(('Team Lineups'!$K$2:$K$2000<>"")*('Team Lineups'!$C$2:$C$2000=$A7)*COUNTIFS('Team Lineups'!$K$2:$K$2000,'Team Lineups'!$K$2:$K$2000,'Team Lineups'!$C$2:$C$2000,AF$1))} -> 1
A8: Alessandro C | B8: {=SUMPRODUCT(('Team Lineups'!$K$2:$K$2000<>"")*('Team Lineups'!$C$2:$C$2000=$A8)*COUNTIFS('Team Lineups'!$K$2:$K$2000,'Team Lineups'!$K$2:$K$2000,'Team Lineups'!$C$2:$C$2000,B$1))} -> 3 | C8: {=SUMPRODUCT(('Team Lineups'!$K$2:$K$2000<>"")*('Team Lineups'!$C$2:$C$2000=$A8)*COUNTIFS('Team Lineups'!$K$2:$K$2000,'Team Lineups'!$K$2:$K$2000,'Team Lineups'!$C$2:$C$2000,C$1))} -> 2 | D8: {=SUMPRODUCT(('Team Lineups'!$K$2:$K$2000<>"")*('Team Lineups'!$C$2:$C$2000=$A8)*COUNTIFS('Team Lineups'!$K$2:$K$2000,'Team Lineups'!$K$2:$K$2000,'Team Lineups'!$C$2:$C$2000,D$1))} -> 2 | E8: {=SUMPRODUCT(('Team Lineups'!$K$2:$K$2000<>"")*('Team Lineups'!$C$2:$C$2000=$A8)*COUNTIFS('Team Lineups'!$K$2:$K$2000,'Team Lineups'!$K$2:$K$2000,'Team Lineups'!$C$2:$C$2000,E$1))} -> 0 | F8: {=SUMPRODUCT(('Team Lineups'!$K$2:$K$2000<>"")*('Team Lineups'!$C$2:$C$2000=$A8)*COUNTIFS('Team Lineups'!$K$2:$K$2000,'Team Lineups'!$K$2:$K$2000,'Team Lineups'!$C$2:$C$2000,F$1))} -> 2 | G8: {=SUMPRODUCT(('Team Lineups'!$K$2:$K$2000<>"")*('Team Lineups'!$C$2:$C$2000=$A8)*COUNTIFS('Team Lineups'!$K$2:$K$2000,'Team Lineups'!$K$2:$K$2000,'Team Lineups'!$C$2:$C$2000,G$1))} -> 4 | H8: NA | I8: {=SUMPRODUCT(('Team Lineups'!$K$2:$K$2000<>"")*('Team Lineups'!$C$2:$C$2000=$A8)*COUNTIFS('Team Lineups'!$K$2:$K$2000,'Team Lineups'!$K$2:$K$2000,'Team Lineups'!$C$2:$C$2000,I$1))} -> 6 | J8: {=SUMPRODUCT(('Team Lineups'!$K$2:$K$2000<>"")*('Team Lineups'!$C$2:$C$2000=$A8)*COUNTIFS('Team Lineups'!$K$2:$K$2000,'Team Lineups'!$K$2:$K$2000,'Team Lineups'!$C$2:$C$2000,J$1))} -> 2 | K8: {=SUMPRODUCT(('Team Lineups'!$K$2:$K$2000<>"")*('Team Lineups'!$C$2:$C$2000=$A8)*COUNTIFS('Team Lineups'!$K$2:$K$2000,'Team Lineups'!$K$2:$K$2000,'Team Lineups'!$C$2:$C$2000,K$1))} -> 1 | L8: {=SUMPRODUCT(('Team Lineups'!$K$2:$K$2000<>"")*('Team Lineups'!$C$2:$C$2000=$A8)*COUNTIFS('Team Lineups'!$K$2:$K$2000,'Team Lineups'!$K$2:$K$2000,'Team Lineups'!$C$2:$C$2000,L$1))} -> 1 | M8: {=SUMPRODUCT(('Team Lineups'!$K$2:$K$2000<>"")*('Team Lineups'!$C$2:$C$2000=$A8)*COUNTIFS('Team Lineups'!$K$2:$K$2000,'Team Lineups'!$K$2:$K$2000,'Team Lineups'!$C$2:$C$2000,M$1))} -> 4 | N8: {=SUMPRODUCT(('Team Lineups'!$K$2:$K$2000<>"")*('Team Lineups'!$C$2:$C$2000=$A8)*COUNTIFS('Team Lineups'!$K$2:$K$2000,'Team Lineups'!$K$2:$K$2000,'Team Lineups'!$C$2:$C$2000,N$1))} -> 3 | O8: {=SUMPRODUCT(('Team Lineups'!$K$2:$K$2000<>"")*('Team Lineups'!$C$2:$C$2000=$A8)*COUNTIFS('Team Lineups'!$K$2:$K$2000,'Team Lineups'!$K$2:$K$2000,'Team Lineups'!$C$2:$C$2000,O$1))} -> 3 | P8: {=SUMPRODUCT(('Team Lineups'!$K$2:$K$2000<>"")*('Team Lineups'!$C$2:$C$2000=$A8)*COUNTIFS('Team Lineups'!$K$2:$K$2000,'Team Lineups'!$K$2:$K$2000,'Team Lineups'!$C$2:$C$2000,P$1))} -> 1 | ... AF8: {=SUMPRODUCT(('Team Lineups'!$K$2:$K$2000<>"")*('Team Lineups'!$C$2:$C$2000=$A8)*COUNTIFS('Team Lineups'!$K$2:$K$2000,'Team Lineups'!$K$2:$K$2000,'Team Lineups'!$C$2:$C$2000,AF$1))} -> 0
A9: Lorenzo | B9: {=SUMPRODUCT(('Team Lineups'!$K$2:$K$2000<>"")*('Team Lineups'!$C$2:$C$2000=$A9)*COUNTIFS('Team Lineups'!$K$2:$K$2000,'Team Lineups'!$K$2:$K$2000,'Team Lineups'!$C$2:$C$2000,B$1))} -> 3 | C9: {=SUMPRODUCT(('Team Lineups'!$K$2:$K$2000<>"")*('Team Lineups'!$C$2:$C$2000=$A9)*COUNTIFS('Team Lineups'!$K$2:$K$2000,'Team Lineups'!$K$2:$K$2000,'Team Lineups'!$C$2:$C$2000,C$1))} -> 2 | D9: {=SUMPRODUCT(('Team Lineups'!$K$2:$K$2000<>"")*('Team Lineups'!$C$2:$C$2000=$A9)*COUNTIFS('Team Lineups'!$K$2:$K$2000,'Team Lineups'!$K$2:$K$2000,'Team Lineups'!$C$2:$C$2000,D$1))} -> 4 | E9: {=SUMPRODUCT(('Team Lineups'!$K$2:$K$2000<>"")*('Team Lineups'!$C$2:$C$2000=$A9)*COUNTIFS('Team Lineups'!$K$2:$K$2000,'Team Lineups'!$K$2:$K$2000,'Team Lineups'!$C$2:$C$2000,E$1))} -> 2 | F9: {=SUMPRODUCT(('Team Lineups'!$K$2:$K$2000<>"")*('Team Lineups'!$C$2:$C$2000=$A9)*COUNTIFS('Team Lineups'!$K$2:$K$2000,'Team Lineups'!$K$2:$K$2000,'Team Lineups'!$C$2:$C$2000,F$1))} -> 4 | G9: {=SUMPRODUCT(('Team Lineups'!$K$2:$K$2000<>"")*('Team Lineups'!$C$2:$C$2000=$A9)*COUNTIFS('Team Lineups'!$K$2:$K$2000,'Team Lineups'!$K$2:$K$2000,'Team Lineups'!$C$2:$C$2000,G$1))} -> 5 | H9: {=SUMPRODUCT(('Team Lineups'!$K$2:$K$2000<>"")*('Team Lineups'!$C$2:$C$2000=$A9)*COUNTIFS('Team Lineups'!$K$2:$K$2000,'Team Lineups'!$K$2:$K$2000,'Team Lineups'!$C$2:$C$2000,H$1))} -> 6 | I9: NA | J9: {=SUMPRODUCT(('Team Lineups'!$K$2:$K$2000<>"")*('Team Lineups'!$C$2:$C$2000=$A9)*COUNTIFS('Team Lineups'!$K$2:$K$2000,'Team Lineups'!$K$2:$K$2000,'Team Lineups'!$C$2:$C$2000,J$1))} -> 2 | K9: {=SUMPRODUCT(('Team Lineups'!$K$2:$K$2000<>"")*('Team Lineups'!$C$2:$C$2000=$A9)*COUNTIFS('Team Lineups'!$K$2:$K$2000,'Team Lineups'!$K$2:$K$2000,'Team Lineups'!$C$2:$C$2000,K$1))} -> 1 | L9: {=SUMPRODUCT(('Team Lineups'!$K$2:$K$2000<>"")*('Team Lineups'!$C$2:$C$2000=$A9)*COUNTIFS('Team Lineups'!$K$2:$K$2000,'Team Lineups'!$K$2:$K$2000,'Team Lineups'!$C$2:$C$2000,L$1))} -> 3 | M9: {=SUMPRODUCT(('Team Lineups'!$K$2:$K$2000<>"")*('Team Lineups'!$C$2:$C$2000=$A9)*COUNTIFS('Team Lineups'!$K$2:$K$2000,'Team Lineups'!$K$2:$K$2000,'Team Lineups'!$C$2:$C$2000,M$1))} -> 4 | N9: {=SUMPRODUCT(('Team Lineups'!$K$2:$K$2000<>"")*('Team Lineups'!$C$2:$C$2000=$A9)*COUNTIFS('Team Lineups'!$K$2:$K$2000,'Team Lineups'!$K$2:$K$2000,'Team Lineups'!$C$2:$C$2000,N$1))} -> 3 | O9: {=SUMPRODUCT(('Team Lineups'!$K$2:$K$2000<>"")*('Team Lineups'!$C$2:$C$2000=$A9)*COUNTIFS('Team Lineups'!$K$2:$K$2000,'Team Lineups'!$K$2:$K$2000,'Team Lineups'!$C$2:$C$2000,O$1))} -> 2 | P9: {=SUMPRODUCT(('Team Lineups'!$K$2:$K$2000<>"")*('Team Lineups'!$C$2:$C$2000=$A9)*COUNTIFS('Team Lineups'!$K$2:$K$2000,'Team Lineups'!$K$2:$K$2000,'Team Lineups'!$C$2:$C$2000,P$1))} -> 1 | Q9: {=SUMPRODUCT(('Team Lineups'!$K$2:$K$2000<>"")*('Team Lineups'!$C$2:$C$2000=$A9)*COUNTIFS('Team Lineups'!$K$2:$K$2000,'Team Lineups'!$K$2:$K$2000,'Team Lineups'!$C$2:$C$2000,Q$1))} -> 4 | ... AF9: {=SUMPRODUCT(('Team Lineups'!$K$2:$K$2000<>"")*('Team Lineups'!$C$2:$C$2000=$A9)*COUNTIFS('Team Lineups'!$K$2:$K$2000,'Team Lineups'!$K$2:$K$2000,'Team Lineups'!$C$2:$C$2000,AF$1))} -> 0
A10: Pranav | B10: {=SUMPRODUCT(('Team Lineups'!$K$2:$K$2000<>"")*('Team Lineups'!$C$2:$C$2000=$A10)*COUNTIFS('Team Lineups'!$K$2:$K$2000,'Team Lineups'!$K$2:$K$2000,'Team Lineups'!$C$2:$C$2000,B$1))} -> 0 | C10: {=SUMPRODUCT(('Team Lineups'!$K$2:$K$2000<>"")*('Team Lineups'!$C$2:$C$2000=$A10)*COUNTIFS('Team Lineups'!$K$2:$K$2000,'Team Lineups'!$K$2:$K$2000,'Team Lineups'!$C$2:$C$2000,C$1))} -> 0 | D10: {=SUMPRODUCT(('Team Lineups'!$K$2:$K$2000<>"")*('Team Lineups'!$C$2:$C$2000=$A10)*COUNTIFS('Team Lineups'!$K$2:$K$2000,'Team Lineups'!$K$2:$K$2000,'Team Lineups'!$C$2:$C$2000,D$1))} -> 0 | E10: {=SUMPRODUCT(('Team Lineups'!$K$2:$K$2000<>"")*('Team Lineups'!$C$2:$C$2000=$A10)*COUNTIFS('Team Lineups'!$K$2:$K$2000,'Team Lineups'!$K$2:$K$2000,'Team Lineups'!$C$2:$C$2000,E$1))} -> 0 | F10: {=SUMPRODUCT(('Team Lineups'!$K$2:$K$2000<>"")*('Team Lineups'!$C$2:$C$2000=$A10)*COUNTIFS('Team Lineups'!$K$2:$K$2000,'Team Lineups'!$K$2:$K$2000,'Team Lineups'!$C$2:$C$2000,F$1))} -> 0 | G10: {=SUMPRODUCT(('Team Lineups'!$K$2:$K$2000<>"")*('Team Lineups'!$C$2:$C$2000=$A10)*COUNTIFS('Team Lineups'!$K$2:$K$2000,'Team Lineups'!$K$2:$K$2000,'Team Lineups'!$C$2:$C$2000,G$1))} -> 2 | H10: {=SUMPRODUCT(('Team Lineups'!$K$2:$K$2000<>"")*('Team Lineups'!$C$2:$C$2000=$A10)*COUNTIFS('Team Lineups'!$K$2:$K$2000,'Team Lineups'!$K$2:$K$2000,'Team Lineups'!$C$2:$C$2000,H$1))} -> 2 | I10: {=SUMPRODUCT(('Team Lineups'!$K$2:$K$2000<>"")*('Team Lineups'!$C$2:$C$2000=$A10)*COUNTIFS('Team Lineups'!$K$2:$K$2000,'Team Lineups'!$K$2:$K$2000,'Team Lineups'!$C$2:$C$2000,I$1))} -> 2 | J10: NA | K10: {=SUMPRODUCT(('Team Lineups'!$K$2:$K$2000<>"")*('Team Lineups'!$C$2:$C$2000=$A10)*COUNTIFS('Team Lineups'!$K$2:$K$2000,'Team Lineups'!$K$2:$K$2000,'Team Lineups'!$C$2:$C$2000,K$1))} -> 1 | L10: {=SUMPRODUCT(('Team Lineups'!$K$2:$K$2000<>"")*('Team Lineups'!$C$2:$C$2000=$A10)*COUNTIFS('Team Lineups'!$K$2:$K$2000,'Team Lineups'!$K$2:$K$2000,'Team Lineups'!$C$2:$C$2000,L$1))} -> 0 | M10: {=SUMPRODUCT(('Team Lineups'!$K$2:$K$2000<>"")*('Team Lineups'!$C$2:$C$2000=$A10)*COUNTIFS('Team Lineups'!$K$2:$K$2000,'Team Lineups'!$K$2:$K$2000,'Team Lineups'!$C$2:$C$2000,M$1))} -> 0 | N10: {=SUMPRODUCT(('Team Lineups'!$K$2:$K$2000<>"")*('Team Lineups'!$C$2:$C$2000=$A10)*COUNTIFS('Team Lineups'!$K$2:$K$2000,'Team Lineups'!$K$2:$K$2000,'Team Lineups'!$C$2:$C$2000,N$1))} -> 0 | O10: {=SUMPRODUCT(('Team Lineups'!$K$2:$K$2000<>"")*('Team Lineups'!$C$2:$C$2000=$A10)*COUNTIFS('Team Lineups'!$K$2:$K$2000,'Team Lineups'!$K$2:$K$2000,'Team Lineups'!$C$2:$C$2000,O$1))} -> 0 | P10: {=SUMPRODUCT(('Team Lineups'!$K$2:$K$2000<>"")*('Team Lineups'!$C$2:$C$2000=$A10)*COUNTIFS('Team Lineups'!$K$2:$K$2000,'Team Lineups'!$K$2:$K$2000,'Team Lineups'!$C$2:$C$2000,P$1))} -> 1 | Q10: {=SUMPRODUCT(('Team Lineups'!$K$2:$K$2000<>"")*('Team Lineups'!$C$2:$C$2000=$A10)*COUNTIFS('Team Lineups'!$K$2:$K$2000,'Team Lineups'!$K$2:$K$2000,'Team Lineups'!$C$2:$C$2000,Q$1))} -> 1 | R10: {=SUMPRODUCT(('Team Lineups'!$K$2:$K$2000<>"")*('Team Lineups'!$C$2:$C$2000=$A10)*COUNTIFS('Team Lineups'!$K$2:$K$2000,'Team Lineups'!$K$2:$K$2000,'Team Lineups'!$C$2:$C$2000,R$1))} -> 1 | ... AF10: {=SUMPRODUCT(('Team Lineups'!$K$2:$K$2000<>"")*('Team Lineups'!$C$2:$C$2000=$A10)*COUNTIFS('Team Lineups'!$K$2:$K$2000,'Team Lineups'!$K$2:$K$2000,'Team Lineups'!$C$2:$C$2000,AF$1))} -> 0
A11: Damian | B11: {=SUMPRODUCT(('Team Lineups'!$K$2:$K$2000<>"")*('Team Lineups'!$C$2:$C$2000=$A11)*COUNTIFS('Team Lineups'!$K$2:$K$2000,'Team Lineups'!$K$2:$K$2000,'Team Lineups'!$C$2:$C$2000,B$1))} -> 0 | C11: {=SUMPRODUCT(('Team Lineups'!$K$2:$K$2000<>"")*('Team Lineups'!$C$2:$C$2000=$A11)*COUNTIFS('Team Lineups'!$K$2:$K$2000,'Team Lineups'!$K$2:$K$2000,'Team Lineups'!$C$2:$C$2000,C$1))} -> 0 | D11: {=SUMPRODUCT(('Team Lineups'!$K$2:$K$2000<>"")*('Team Lineups'!$C$2:$C$2000=$A11)*COUNTIFS('Team Lineups'!$K$2:$K$2000,'Team Lineups'!$K$2:$K$2000,'Team Lineups'!$C$2:$C$2000,D$1))} -> 0 | E11: {=SUMPRODUCT(('Team Lineups'!$K$2:$K$2000<>"")*('Team Lineups'!$C$2:$C$2000=$A11)*COUNTIFS('Team Lineups'!$K$2:$K$2000,'Team Lineups'!$K$2:$K$2000,'Team Lineups'!$C$2:$C$2000,E$1))} -> 0 | F11: {=SUMPRODUCT(('Team Lineups'!$K$2:$K$2000<>"")*('Team Lineups'!$C$2:$C$2000=$A11)*COUNTIFS('Team Lineups'!$K$2:$K$2000,'Team Lineups'!$K$2:$K$2000,'Team Lineups'!$C$2:$C$2000,F$1))} -> 0 | G11: {=SUMPRODUCT(('Team Lineups'!$K$2:$K$2000<>"")*('Team Lineups'!$C$2:$C$2000=$A11)*COUNTIFS('Team Lineups'!$K$2:$K$2000,'Team Lineups'!$K$2:$K$2000,'Team Lineups'!$C$2:$C$2000,G$1))} -> 1 | H11: {=SUMPRODUCT(('Team Lineups'!$K$2:$K$2000<>"")*('Team Lineups'!$C$2:$C$2000=$A11)*COUNTIFS('Team Lineups'!$K$2:$K$2000,'Team Lineups'!$K$2:$K$2000,'Team Lineups'!$C$2:$C$2000,H$1))} -> 1 | I11: {=SUMPRODUCT(('Team Lineups'!$K$2:$K$2000<>"")*('Team Lineups'!$C$2:$C$2000=$A11)*COUNTIFS('Team Lineups'!$K$2:$K$2000,'Team Lineups'!$K$2:$K$2000,'Team Lineups'!$C$2:$C$2000,I$1))} -> 1 | J11: {=SUMPRODUCT(('Team Lineups'!$K$2:$K$2000<>"")*('Team Lineups'!$C$2:$C$2000=$A11)*COUNTIFS('Team Lineups'!$K$2:$K$2000,'Team Lineups'!$K$2:$K$2000,'Team Lineups'!$C$2:$C$2000,J$1))} -> 1 | K11: NA | L11: {=SUMPRODUCT(('Team Lineups'!$K$2:$K$2000<>"")*('Team Lineups'!$C$2:$C$2000=$A11)*COUNTIFS('Team Lineups'!$K$2:$K$2000,'Team Lineups'!$K$2:$K$2000,'Team Lineups'!$C$2:$C$2000,L$1))} -> 0 | M11: {=SUMPRODUCT(('Team Lineups'!$K$2:$K$2000<>"")*('Team Lineups'!$C$2:$C$2000=$A11)*COUNTIFS('Team Lineups'!$K$2:$K$2000,'Team Lineups'!$K$2:$K$2000,'Team Lineups'!$C$2:$C$2000,M$1))} -> 0 | N11: {=SUMPRODUCT(('Team Lineups'!$K$2:$K$2000<>"")*('Team Lineups'!$C$2:$C$2000=$A11)*COUNTIFS('Team Lineups'!$K$2:$K$2000,'Team Lineups'!$K$2:$K$2000,'Team Lineups'!$C$2:$C$2000,N$1))} -> 0 | O11: {=SUMPRODUCT(('Team Lineups'!$K$2:$K$2000<>"")*('Team Lineups'!$C$2:$C$2000=$A11)*COUNTIFS('Team Lineups'!$K$2:$K$2000,'Team Lineups'!$K$2:$K$2000,'Team Lineups'!$C$2:$C$2000,O$1))} -> 0 | P11: {=SUMPRODUCT(('Team Lineups'!$K$2:$K$2000<>"")*('Team Lineups'!$C$2:$C$2000=$A11)*COUNTIFS('Team Lineups'!$K$2:$K$2000,'Team Lineups'!$K$2:$K$2000,'Team Lineups'!$C$2:$C$2000,P$1))} -> 0 | Q11: {=SUMPRODUCT(('Team Lineups'!$K$2:$K$2000<>"")*('Team Lineups'!$C$2:$C$2000=$A11)*COUNTIFS('Team Lineups'!$K$2:$K$2000,'Team Lineups'!$K$2:$K$2000,'Team Lineups'!$C$2:$C$2000,Q$1))} -> 0 | R11: {=SUMPRODUCT(('Team Lineups'!$K$2:$K$2000<>"")*('Team Lineups'!$C$2:$C$2000=$A11)*COUNTIFS('Team Lineups'!$K$2:$K$2000,'Team Lineups'!$K$2:$K$2000,'Team Lineups'!$C$2:$C$2000,R$1))} -> 0 | S11: {=SUMPRODUCT(('Team Lineups'!$K$2:$K$2000<>"")*('Team Lineups'!$C$2:$C$2000=$A11)*COUNTIFS('Team Lineups'!$K$2:$K$2000,'Team Lineups'!$K$2:$K$2000,'Team Lineups'!$C$2:$C$2000,S$1))} -> 0 | ... AF11: {=SUMPRODUCT(('Team Lineups'!$K$2:$K$2000<>"")*('Team Lineups'!$C$2:$C$2000=$A11)*COUNTIFS('Team Lineups'!$K$2:$K$2000,'Team Lineups'!$K$2:$K$2000,'Team Lineups'!$C$2:$C$2000,AF$1))} -> 0
A12: Sergio | B12: {=SUMPRODUCT(('Team Lineups'!$K$2:$K$2000<>"")*('Team Lineups'!$C$2:$C$2000=$A12)*COUNTIFS('Team Lineups'!$K$2:$K$2000,'Team Lineups'!$K$2:$K$2000,'Team Lineups'!$C$2:$C$2000,B$1))} -> 1 | C12: {=SUMPRODUCT(('Team Lineups'!$K$2:$K$2000<>"")*('Team Lineups'!$C$2:$C$2000=$A12)*COUNTIFS('Team Lineups'!$K$2:$K$2000,'Team Lineups'!$K$2:$K$2000,'Team Lineups'!$C$2:$C$2000,C$1))} -> 3 | D12: {=SUMPRODUCT(('Team Lineups'!$K$2:$K$2000<>"")*('Team Lineups'!$C$2:$C$2000=$A12)*COUNTIFS('Team Lineups'!$K$2:$K$2000,'Team Lineups'!$K$2:$K$2000,'Team Lineups'!$C$2:$C$2000,D$1))} -> 6 | E12: {=SUMPRODUCT(('Team Lineups'!$K$2:$K$2000<>"")*('Team Lineups'!$C$2:$C$2000=$A12)*COUNTIFS('Team Lineups'!$K$2:$K$2000,'Team Lineups'!$K$2:$K$2000,'Team Lineups'!$C$2:$C$2000,E$1))} -> 5 | F12: {=SUMPRODUCT(('Team Lineups'!$K$2:$K$2000<>"")*('Team Lineups'!$C$2:$C$2000=$A12)*COUNTIFS('Team Lineups'!$K$2:$K$2000,'Team Lineups'!$K$2:$K$2000,'Team Lineups'!$C$2:$C$2000,F$1))} -> 5 | G12: {=SUMPRODUCT(('Team Lineups'!$K$2:$K$2000<>"")*('Team Lineups'!$C$2:$C$2000=$A12)*COUNTIFS('Team Lineups'!$K$2:$K$2000,'Team Lineups'!$K$2:$K$2000,'Team Lineups'!$C$2:$C$2000,G$1))} -> 3 | H12: {=SUMPRODUCT(('Team Lineups'!$K$2:$K$2000<>"")*('Team Lineups'!$C$2:$C$2000=$A12)*COUNTIFS('Team Lineups'!$K$2:$K$2000,'Team Lineups'!$K$2:$K$2000,'Team Lineups'!$C$2:$C$2000,H$1))} -> 1 | I12: {=SUMPRODUCT(('Team Lineups'!$K$2:$K$2000<>"")*('Team Lineups'!$C$2:$C$2000=$A12)*COUNTIFS('Team Lineups'!$K$2:$K$2000,'Team Lineups'!$K$2:$K$2000,'Team Lineups'!$C$2:$C$2000,I$1))} -> 3 | ... K12: {=SUMPRODUCT(('Team Lineups'!$K$2:$K$2000<>"")*('Team Lineups'!$C$2:$C$2000=$A12)*COUNTIFS('Team Lineups'!$K$2:$K$2000,'Team Lineups'!$K$2:$K$2000,'Team Lineups'!$C$2:$C$2000,K$1))} -> 0 | L12: NA | M12: {=SUMPRODUCT(('Team Lineups'!$K$2:$K$2000<>"")*('Team Lineups'!$C$2:$C$2000=$A12)*COUNTIFS('Team Lineups'!$K$2:$K$2000,'Team Lineups'!$K$2:$K$2000,'Team Lineups'!$C$2:$C$2000,M$1))} -> 3 | N12: {=SUMPRODUCT(('Team Lineups'!$K$2:$K$2000<>"")*('Team Lineups'!$C$2:$C$2000=$A12)*COUNTIFS('Team Lineups'!$K$2:$K$2000,'Team Lineups'!$K$2:$K$2000,'Team Lineups'!$C$2:$C$2000,N$1))} -> 4 | O12: {=SUMPRODUCT(('Team Lineups'!$K$2:$K$2000<>"")*('Team Lineups'!$C$2:$C$2000=$A12)*COUNTIFS('Team Lineups'!$K$2:$K$2000,'Team Lineups'!$K$2:$K$2000,'Team Lineups'!$C$2:$C$2000,O$1))} -> 2 | P12: {=SUMPRODUCT(('Team Lineups'!$K$2:$K$2000<>"")*('Team Lineups'!$C$2:$C$2000=$A12)*COUNTIFS('Team Lineups'!$K$2:$K$2000,'Team Lineups'!$K$2:$K$2000,'Team Lineups'!$C$2:$C$2000,P$1))} -> 1 | Q12: {=SUMPRODUCT(('Team Lineups'!$K$2:$K$2000<>"")*('Team Lineups'!$C$2:$C$2000=$A12)*COUNTIFS('Team Lineups'!$K$2:$K$2000,'Team Lineups'!$K$2:$K$2000,'Team Lineups'!$C$2:$C$2000,Q$1))} -> 4 | R12: {=SUMPRODUCT(('Team Lineups'!$K$2:$K$2000<>"")*('Team Lineups'!$C$2:$C$2000=$A12)*COUNTIFS('Team Lineups'!$K$2:$K$2000,'Team Lineups'!$K$2:$K$2000,'Team Lineups'!$C$2:$C$2000,R$1))} -> 2 | S12: {=SUMPRODUCT(('Team Lineups'!$K$2:$K$2000<>"")*('Team Lineups'!$C$2:$C$2000=$A12)*COUNTIFS('Team Lineups'!$K$2:$K$2000,'Team Lineups'!$K$2:$K$2000,'Team Lineups'!$C$2:$C$2000,S$1))} -> 4 | T12: {=SUMPRODUCT(('Team Lineups'!$K$2:$K$2000<>"")*('Team Lineups'!$C$2:$C$2000=$A12)*COUNTIFS('Team Lineups'!$K$2:$K$2000,'Team Lineups'!$K$2:$K$2000,'Team Lineups'!$C$2:$C$2000,T$1))} -> 1 | ... AF12: {=SUMPRODUCT(('Team Lineups'!$K$2:$K$2000<>"")*('Team Lineups'!$C$2:$C$2000=$A12)*COUNTIFS('Team Lineups'!$K$2:$K$2000,'Team Lineups'!$K$2:$K$2000,'Team Lineups'!$C$2:$C$2000,AF$1))} -> 0
